Workbook

Sheet Formosa
A1: Fornecedores | C1: =50000 -> 50000
A3: Rivoli | C3: 7872 | D3: 2 rendas
A4: Suvita | C4: 8866 | D4: 20% leasing
A5: Gastro | C5: 10205 | D5: Bancadas
A6: Sara | C6: 2700 | D6: Projeto
A7: Sklum | C7: 869 | D7: Mesas
A8: Aexperial | C8: 2937.73 | D8: Carapinas
A9: Decorestudio | C9: 526 | D9: Luminoso - 40% do valor total
A10: Protame | C10: 1878.38 | D10: POS Formosa
A11: Cutlab | C11: 1166.5 | D11: Vinil Recortado 583,25 + 583,25

Sheet BD_Movimentos
A1: Data | B1: Tipo | C1: Empresa | D1: Nome Comercial | E1: Fatura | F1: Valor Real | G1: Data Vencimento | H1: Estado | I1: Centro Custo | J1: Agen confir | K1: Data Pagamento | L1: Valor Prev. | M1: Descrição
A2: 45756 | B2: Pagamento | C2: yh6 | E2: FT25/575 | F2: -67.22 | H2: Pago | I2: Matosinhos | K2: 45782 | L2: =F2 -> -67.22
A3: 45128 | B3: Pagamento | C3: A Prestigiosa | E3: 5159 | F3: -99.26 | H3: Pago | L3: =F3 -> -99.26 | M3: coco
A4: 45194 | B4: Pagamento | C4: A prestigiosa | E4: FT23/6803 | F4: -34.42 | H4: Pago | L4: =F4 -> -34.42 | M4: Coco
A5: 45196 | B5: Pagamento | C5: A prestigiosa | E5: FT 23/6864 | F5: -127.5 | H5: Pago | L5: =F5 -> -127.5 | M5: Leite de coco
A6: 45259 | B6: Pagamento | C6: A prestigiosa | E6: FT 23/8170 | F6: -111.51 | H6: Pago | L6: =F6 -> -111.51 | M6: Coco
A7: 45341 | B7: Pagamento | C7: A Prestigiosa | E7: FT 24/10609 | F7: -180.1 | H7: Pago | L7: =F7 -> -180.1 | M7: Coco
A8: 45796 | B8: Pagamento | C8: A prestigiosa | E8: FT25/9513 | F8: -311 | H8: Pago | I8: Matosinhos | K8: 45796
A9: 45514 | B9: Pagamento | C9: ADENE | E9: FT 24/418287 | F9: -166.05 | H9: Pago | I9: Baixa | L9: =F9 -> -166.05 | M9: Taxa certificado energético - PT50 0035 0447 0005576690067
A10: 45812 | B10: Recebimento | C10: Abóbada Verde | E10: FA 1A2501/83 | F10: 75 | H10: Pago | I10: B2B | K10: 45819 | L10: =F10 -> 75
A11: 45303 | B11: Pagamento | C11: Aexperial | F11: -2937.73 | H11: Pago | L11: =F11 -> -2937.73 | M11: Carapinas
A12: 45786 | B12: Pagamento | C12: Aexperial | E12: PF 25/311 | F12: -1562.44 | H12: Pago | I12: Matosinhos | K12: 45789 | M12: Carapinas
A13: 45303 | B13: Pagamento | C13: Ageas | E13: 74548945 | F13: -15.23 | H13: Pago | L13: =F13 -> -15.23 | M13: Entidade: 23445 REF: 574889165 Valor: 15,23 /(até ao final do mês)
A14: 45784 | B14: Pagamento | C14: AGEAS | F14: -1590.79 | G14: 45787 | H14: Pago | I14: Matosinhos | K14: 45786 | L14: =F14 -> -1590.79 | M14: Apólice seguro A.Trabalho 20776 | 973 638 193
B15: Pagamento | C15: Aluguer garagem | F15: -400 | H15: Pago | I15: Matosinhos | K15: 45912 | M15: Renda Setembro e Outubro 25
A16: 45939 | B16: Pagamento | C16: AF System | E16: Orc25/185 | F16: -13000 | H16: Suspenso | I16: Produção | M16: Transf de sinal de 1500€ a 14/10/2025
A17: 45853 | B17: Pagamento | C17: Aluguer garagem | F17: -400 | H17: Pago | I17: Matosinhos | M17: Renda Julho e Agosto 25
A18: 45748 | B18: Pagamento | C18: Aluguer garagem | F18: -600 | H18: Pago | I18: Matosinhos | M18: Renda Abril, Maio, Junho 25
B19: Pagamento | C19: Aluguer garagem | F19: -400 | G19: 45962 | H19: Pago | I19: Matosinhos | K19: 45972 | M19: Renda Novembro e Dezembro 25
B20: Pagamento | C20: Aluguer garagem | F20: -400 | G20: 46023 | H20: Pago | I20: Matosinhos | K20: 46038 | L20: Renda Novembro e Dezembro 25 | M20: Renda Jan e Fev 2026
B21: Pagamento | C21: Aluguer garagem | F21: -400 | G21: 46082 | H21: Pago | I21: Matosinhos | K21: 46090 | L21: Renda Novembro e Dezembro 25 | M21: Renda Mar e Abr 2026
A22: 45566 | B22: Pagamento | C22: Ambiese | E22: FT 24/1735 | F22: -42.52 | H22: Pago | I22: Matosinhos | K22: 45454 | L22: =F22 -> -42.52 | M22: Detergentes
A23: 45587 | B23: Pagamento | C23: Ambiese | E23: FT 24/1860 | F23: -87.38 | H23: Pago | I23: Matosinhos | K23: 45454 | L23: =F23 -> -87.38 | M23: Detergentes
A24: 45595 | B24: Pagamento | C24: Ambiese | E24: FT 24/1916 | F24: -139.67 | H24: Pago | I24: Matosinhos | K24: 45454 | L24: =F24 -> -139.67 | M24: Detergentes
A25: 45601 | B25: Pagamento | C25: Ambiese | E25: FT24/1941 | F25: -152.34 | H25: Pago | I25: Matosinhos | K25: 45455 | L25: =F25 -> -152.34
A26: 45601 | B26: Pagamento | C26: Ambiese | E26: FT24/1948 | F26: -14.51 | H26: Pago | I26: Matosinhos | K26: 45455 | L26: =F26 -> -14.51
A27: 45608 | B27: Pagamento | C27: Ambiese | E27: FT24/1991 | F27: -21.27 | H27: Pago | I27: Matosinhos | K27: 45455 | L27: =F27 -> -21.27
A28: 45615 | B28: Pagamento | C28: Ambiese | E28: FT24/2034 | F28: -83.34 | G28: 45615 | H28: Pago | I28: Matosinhos | K28: 45455 | L28: =F28 -> -83.34
A29: 45622 | B29: Pagamento | C29: Ambiese | E29: FT24/2076 | F29: -33.1 | G29: 45622 | H29: Pago | I29: Matosinhos | K29: 45455 | L29: =F29 -> -33.1
A30: 45684 | B30: Pagamento | C30: Ambiese | E30: FT25/135 | F30: -114.43 | G30: 45684 | H30: Pago | I30: Matosinhos | K30: 45695 | L30: =F30 -> -114.43
A31: 45684 | B31: Pagamento | C31: Ambiese | E31: FT25/136 | F31: -21.84 | G31: 45684 | H31: Pago | I31: Matosinhos | K31: 45695 | L31: =F31 -> -21.84
A32: 45693 | B32: Pagamento | C32: Ambiese | E32: FT25/196 | F32: -61.27 | G32: 45693 | H32: Pago | I32: Matosinhos | K32: 45723 | L32: =F32 -> -61.27
A33: 45707 | B33: Pagamento | C33: Ambiese | E33: FT25/291 | F33: -52.85 | G33: 45735 | H33: Pago | I33: Matosinhos | K33: 45723 | L33: =F33 -> -52.85
A34: 45699 | B34: Pagamento | C34: Ambiese | E34: FT25/241 | F34: -21.99 | G34: 45727 | H34: Pago | I34: Matosinhos | K34: 45723 | L34: =F34 -> -21.99
A35: 45714 | B35: Pagamento | C35: Ambiese | E35: FT25/323 | F35: -92.79 | H35: Pago | I35: Matosinhos | K35: 45727 | L35: =F35 -> -92.79
A36: 45699 | B36: Pagamento | C36: Ambiese | E36: FT25/240 | F36: -33.17 | H36: Pago | I36: Bolhao | K36: 45751 | L36: =F36 -> -33.17
A37: 45713 | B37: Pagamento | C37: Ambiese | E37: FT25/322 | F37: -29.86 | H37: Pago | I37: Bolhão | K37: 45751 | L37: =F37 -> -29.86
A38: 45721 | B38: Pagamento | C38: Ambiese | E38: FT25/366 | F38: -106.49 | H38: Pago | I38: Matosinhos | K38: 45751 | L38: =F38 -> -106.49
A39: 45727 | B39: Pagamento | C39: Ambiese | E39: FT25/395 | F39: -33.17 | H39: Pago | I39: Bolhão | K39: 45751 | L39: =F39 -> -33.17
A40: 45727 | B40: Pagamento | C40: Ambiese | E40: FT25/394 | F40: -50.09 | H40: Pago | I40: Matosinhos | K40: 45751 | L40: =F40 -> -50.09
...

Sheet Fundo de Caixa
A1: Valor | B1: Qt | C1: Total | I1: Valor | J1: Qt | K1: Total | M1: Fundo Maneio MAT | O1: 45656 | Q1: Fundo Maneio BOLH | S1: 45659
A2: 0.01 | B2: 277 | C2: =B2*A2 -> 2.77 | I2: 0.01 | K2: =J2*I2 -> 0 | M2: Valor | N2: Qt | O2: Total | Q2: Valor | R2: Qt | S2: Total
A3: 0.02 | B3: 62 | C3: =B3*A3 -> 1.24 | I3: 0.02 | K3: =J3*I3 -> 0 | M3: 0.01 | O3: =N3*M3 -> 0 | Q3: 0.01 | S3: =R3*Q3 -> 0
A4: 0.05 | B4: 4 | C4: =B4*A4 -> 0.2 | I4: 0.05 | K4: =J4*I4 -> 0 | M4: 0.02 | N4: 51 | O4: =N4*M4 -> 1.02 | Q4: 0.02 | S4: =R4*Q4 -> 0
A5: 0.1 | B5: 21 | C5: =B5*A5 -> 2.1 | I5: 0.1 | K5: =J5*I5 -> 0 | M5: 0.05 | O5: =N5*M5 -> 0 | Q5: 0.05 | S5: =R5*Q5 -> 0
A6: 0.2 | B6: 0 | C6: =B6*A6 -> 0 | E6: fundo n+1 | F6: =F8+35 -> 86.31 | I6: 0.2 | K6: =J6*I6 -> 0 | M6: 0.1 | N6: 56 | O6: =N6*M6 -> 5.6 | Q6: 0.1 | S6: =R6*Q6 -> 0
A7: 0.5 | B7: 2 | C7: =B7*A7 -> 1 | I7: 0.5 | K7: =J7*I7 -> 0 | M7: 0.2 | N7: 43 | O7: =N7*M7 -> 8.6 | Q7: 0.2 | S7: =R7*Q7 -> 0
A8: 1 | B8: 30 | C8: =B8*A8 -> 30 | E8: Moedas | F8: =SUM(C2:C9) -> 51.31 | I8: 1 | K8: =J8*I8 -> 0 | M8: 0.5 | N8: 1 | O8: =N8*M8 -> 0.5 | Q8: 0.5 | S8: =R8*Q8 -> 0
A9: 2 | B9: 7 | C9: =B9*A9 -> 14 | E9: Notas | F9: =SUM(C10:C16) -> 0 | I9: 2 | K9: =J9*I9 -> 0 | M9: 1 | N9: 2 | O9: =N9*M9 -> 2 | Q9: 1 | S9: =R9*Q9 -> 0
A10: 5 | B10: 0 | C10: =B10*A10 -> 0 | E10: Total | F10: =C17 -> 51.31 | I10: 5 | K10: =J10*I10 -> 0 | M10: 2 | N10: 1 | O10: =N10*M10 -> 2 | Q10: 2 | S10: =R10*Q10 -> 0
A11: 10 | B11: 0 | C11: =B11*A11 -> 0 | E11: fundo cx | F11: 72.75 | I11: 10 | J11: 21 | K11: =J11*I11 -> 210 | M11: 5 | N11: 5 | O11: =N11*M11 -> 25 | Q11: 5 | S11: =R11*Q11 -> 0
A12: 20 | B12: 0 | C12: =B12*A12 -> 0 | E12: Numerário | F12: =F10-F11 -> -21.44 | I12: 20 | J12: 28 | K12: =J12*I12 -> 560 | M12: 10 | N12: 9 | O12: =N12*M12 -> 90 | Q12: 10 | S12: =R12*Q12 -> 0
A13: 50 | B13: 0 | C13: =B13*A13 -> 0 | I13: 50 | J13: 2 | K13: =J13*I13 -> 100 | M13: 20 | N13: 2 | O13: =N13*M13 -> 40 | Q13: 20 | S13: =R13*Q13 -> 0
A14: 100 | B14: 0 | C14: =B14*A14 -> 0 | I14: 100 | K14: =J14*I14 -> 0 | M14: 50 | O14: =N14*M14 -> 0 | Q14: 50 | S14: =R14*Q14 -> 0
A15: 200 | B15: 0 | C15: =B15*A15 -> 0 | I15: 200 | K15: =J15*I15 -> 0 | M15: 100 | O15: =N15*M15 -> 0 | Q15: 100 | S15: =R15*Q15 -> 0
A16: 500 | B16: 0 | C16: =B16*A16 -> 0 | E16: =355-35 -> 320 | I16: 500 | K16: =J16*I16 -> 0 | M16: 200 | O16: =N16*M16 -> 0 | Q16: 200 | S16: =R16*Q16 -> 0
C17: =SUM(C2:C16) -> 51.31 | K17: =SUM(K2:K16) -> 870 | M17: 500 | O17: =N17*M17 -> 0 | Q17: 500 | S17: =R17*Q17 -> 0
O18: =SUM(O3:O17) -> 174.72 | S18: =SUM(S3:S17) -> 0
S19: 38.21

Sheet Depositos Matosinhos
A1: Dia | B1: Deposito | C1: Num | E1: Pagamentos | F1: Comentario
A2: 44813 | B2: 4575
A3: 44814 | C3: =Setembro!N11 -> 504.8
A4: 44815 | C4: =Setembro!N12 -> 575.93 | D4: 566.33 | F4: O total do multibanco tinha um valor inferior ao registado de 9,60€, compensou no numerário
A5: 44816 | C5: =Setembro!N13 -> 0
A6: 44817 | C6: =Setembro!N14 -> 70.1 | E6: =105.66+68.14+200.88+66 -> 440.68 | F6: Makro (FT023560/033862/027982) / Frutas ( FT 1222)
A7: 44818 | C7: =Setembro!N15 -> 197.82 | E7: 160 | F7: MagoFri (FT 25037/26835/27085) - recibo 5620
A8: 44819 | C8: =Setembro!N16 -> 165.84 | E8: 420 | F8: Progelcone (FT40220215591) - recibo 416940
A9: 44820 | C9: =Setembro!N17 -> 314 | D9: 310
A10: 44821 | C10: =Setembro!N18 -> 543.9
A11: 44822 | C11: =Setembro!N19 -> 593.8
A12: 44823 | C12: =Setembro!N20 -> 0
A13: 44824 | C13: =Setembro!N21 -> 314.96
A14: 44825 | C14: =Setembro!N22 -> 182.68 | E14: =210.9+135.79+259.99 -> 606.68 | F14: Frutas(FT1296)/Makro(ft015314)/Fnac(FT 65850)
A15: 44826 | C15: =Setembro!N23 -> 250.58 | E15: 16.97 | F15: Progelcone (FT40220217257)-recibo416945
A16: 44827 | C16: =Setembro!N24 -> 193.3 | D16: 195 | E16: 40 | F16: lavazzA
A17: 44828 | C17: =Setembro!N25 -> 338.55 | D17: 335
A18: 44829 | C18: =Setembro!N26 -> 371.69 | D18: 360 | F18: Houve um uber pelo menos que não foi registado como uber
A19: 44830 | C19: =Setembro!N27 -> 0
A20: 44831 | C20: =Setembro!N28 -> 99.5
A21: 44832 | C21: =Setembro!N29 -> 72.1 | E21: =87.91+76.24 -> 164.15 | F21: Frutas(FT1336)/Makro (FT015344)
A22: 44833 | C22: =Setembro!N30 -> 96.48 | E22: 345 | F22: Progelcone(FT40220218850)-recibo418634
A23: 44834 | C23: =Setembro!N31 -> 80.4 | E23: 40 | F23: lavazzA
A25: 44835 | C25: =Outubro!N2 -> 479.9
A26: 44836 | C26: =Outubro!N3 -> 315.65
A27: 44837 | C27: =Outubro!N4 -> 0
A28: 44838 | C28: =Outubro!N5 -> 246.05
A29: 44839 | C29: =Outubro!N6 -> 608.44
A30: 44840 | B30: 4480 | C30: =Outubro!N7 -> 94.1
A31: 44841 | C31: =Outubro!N8 -> 149.98
A32: 44842 | C32: =Outubro!N9 -> 245.06
A33: 44843 | C33: =Outubro!N10 -> 193.6 | D33: 195
A34: 44844 | C34: =Outubro!N11 -> 0
A35: 44845 | C35: =Outubro!N12 -> 132.64
A36: 44846 | C36: =Outubro!N13 -> 112.6
A37: 44847 | C37: =Outubro!N14 -> 113.36 | E37: =247+ 8 -> 255 | F37: Progelcone (FT40220220986/FT40220220992)- Recibo 418646 / Pingo Doce
A38: 44848 | C38: =Outubro!N15 -> 102.94
A39: 44849 | C39: =Outubro!N16 -> 236.24
A40: 44850 | C40: =Outubro!N17 -> 205.32 | E40: =49+81.28+61.25+135.46+28.67 -> 355.66 | F40: Tiger/Makro/Homa/Makro/28,67
A41: 44851 | C41: =Outubro!N18 -> 0
...

Sheet Maio
B1: FECHO DO DIA | C1: SALT PAY | D1: SANTANDER | E1: GASTOS C/RECIBO | F1: GASTOS S/RECIBO | G1: GLOVO | H1: UBER EATS | I1: VOLUP | J1: BOLT | K1: NUMERARIO | L1: TOTAL | M1: DEPOSITO | N1: EXTRA | O1: FUNDO CAIXA
A2: 44682 | L2: =C2+D2+E2+F2+G2+H2+I2+J2+K2 -> 0 | M2: =K2-N2 -> 0 | N2: =L2-B2-F2 -> 0
A3: 44683 | L3: =C3+D3+E3+F3+G3+H3+I3+J3+K3 -> 0 | M3: =K3-N3 -> 0 | N3: =L3-B3-F3 -> 0
A4: 44684 | L4: =C4+D4+E4+F4+G4+H4+I4+J4+K4 -> 0 | M4: =K4-N4 -> 0 | N4: =L4-B4-F4 -> 0
A5: 44685 | L5: =C5+D5+E5+F5+G5+H5+I5+J5+K5 -> 0 | M5: =K5-N5 -> 0 | N5: =L5-B5-F5 -> 0
A6: 44686 | L6: =C6+D6+E6+F6+G6+H6+I6+J6+K6 -> 0 | M6: =K6-N6 -> 0 | N6: =L6-B6-F6 -> 0
A7: 44687 | L7: =C7+D7+E7+F7+G7+H7+I7+J7+K7 -> 0 | M7: =K7-N7 -> 0 | N7: =L7-B7-F7 -> 0
A8: 44688 | B8: 251 | C8: 113.16 | D8: 54.35 | K8: 95 | L8: =C8+D8+E8+F8+G8+H8+I8+J8+K8 -> 262.51 | M8: 0 | N8: =L8-B8-F8 -> 11.51 | O8: 80
A9: 44689 | B9: 1073.7 | C9: 659.3 | D9: 56.5 | K9: 360 | L9: =C9+D9+E9+F9+G9+H9+I9+J9+K9 -> 1075.8 | M9: =K9-N9 -> 357.9 | N9: =L9-B9-F9 -> 2.1 | O9: 77.21
A10: 44690 | B10: 200.9 | C10: 126.21 | D10: 0 | K10: 75 | L10: =C10+D10+E10+F10+G10+H10+I10+J10+K10 -> 201.21 | M10: =K10-N10 -> 74.69 | N10: =L10-B10-F10 -> 0.31 | O10: 83.11
A11: 44691 | B11: 203.8 | C11: 112.9 | D11: 0 | K11: 95 | L11: =C11+D11+E11+F11+G11+H11+I11+J11+K11 -> 207.9 | M11: =K11-N11 -> 90.9 | N11: =L11-B11-F11 -> 4.1 | O11: 80
A12: 44692 | B12: 311.5 | C12: 228.4 | D12: 8.7 | K12: 95 | L12: =C12+D12+E12+F12+G12+H12+I12+J12+K12 -> 332.1 | M12: =K12-N12 -> 74.4 | N12: =L12-B12-F12 -> 20.6 | O12: 80
A13: 44693 | B13: 237.7 | C13: 145.9 | D13: 37.5 | E13: 0 | F13: 0 | G13: 0 | H13: 0 | I13: 0 | J13: 0 | K13: 60 | L13: =C13+D13+E13+F13+G13+H13+I13+J13+K13 -> 243.4 | M13: =K13-N13 -> 54.3 | N13: =L13-B13-F13 -> 5.7 | O13: 86
A14: 44694 | B14: 562.22 | C14: 346.12 | D14: 18.1 | E14: 0 | F14: 0 | G14: 0 | H14: 0 | I14: 0 | J14: 0 | K14: 210 | L14: =C14+D14+E14+F14+G14+H14+I14+J14+K14 -> 574.22 | M14: =K14-N14 -> 198 | N14: =L14-B14-F14 -> 12 | O14: 89.21
A15: 44695 | B15: 1108.8 | C15: 538.6 | D15: 63.8 | E15: =2.5+5.99 -> 8.49 | F15: 0 | G15: 0 | H15: 0 | I15: 0 | J15: 0 | K15: 510 | L15: =C15+D15+E15+F15+G15+H15+I15+J15+K15 -> 1120.89 | M15: =K15-N15 -> 497.91 | N15: =L15-B15-F15 -> 12.09 | O15: 89.61
A16: 44696 | B16: 501.66 | C16: 161.3 | D16: 104.3 | E16: 36.3 | F16: 0 | G16: 0 | H16: 0 | I16: 0 | J16: 0 | K16: 200 | L16: =C16+D16+E16+F16+G16+H16+I16+J16+K16 -> 501.9 | M16: =K16-N16 -> 199.76 | N16: =L16-B16-F16 -> 0.24 | O16: 89.5
A17: 44697 | B17: 115.3 | C17: 49.8 | D17: 8.6 | E17: 5.45 | F17: 0 | G17: 0 | H17: 0 | I17: 0 | J17: 0 | K17: 55 | L17: =C17+D17+E17+F17+G17+H17+I17+J17+K17 -> 118.85 | M17: =K17-N17 -> 51.45 | N17: =L17-B17-F17 -> 3.55
A18: 44698 | B18: 135.8 | C18: 66.9 | D18: 18.8 | E18: 0 | F18: 0 | G18: 0 | H18: 0 | I18: 0 | J18: 0 | K18: 55 | L18: =C18+D18+E18+F18+G18+H18+I18+J18+K18 -> 140.7 | M18: =K18-N18 -> 50.1 | N18: =L18-B18-F18 -> 4.9 | O18: 81.04
A19: 44699 | B19: 300.74 | C19: 124.14 | D19: 36.2 | E19: 0 | F19: 0 | G19: 0 | H19: 0 | I19: 0 | J19: 0 | K19: 145 | L19: =C19+D19+E19+F19+G19+H19+I19+J19+K19 -> 305.34 | M19: =K19-N19 -> 140.4 | N19: =L19-B19-F19 -> 4.6 | O19: 76.8
A20: 44700 | B20: 441.3 | C20: 260.9 | D20: 35 | E20: 2.79 | F20: 0 | G20: 0 | H20: 0 | I20: 0 | J20: 0 | K20: 150 | L20: =C20+D20+E20+F20+G20+H20+I20+J20+K20 -> 448.69 | M20: =K20-N20 -> 142.61 | N20: =L20-B20-F20 -> 7.39 | O20: 80
A21: 44701 | B21: 1355.51 | C21: 659.1 | D21: 219.8 | E21: =1.16+6.72 -> 7.88 | F21: 15 | G21: 0 | H21: 0 | I21: 0 | J21: 0 | K21: 470 | L21: =C21+D21+E21+F21+G21+H21+I21+J21+K21 -> 1371.78 | M21: =K21-N21 -> 468.73 | N21: =L21-B21-F21 -> 1.27 | O21: 88.15
A22: 44702 | B22: 902.1 | C22: 469.72 | D22: 114.4 | E22: =32.85+7.01+70.11 -> 109.97 | F22: 0 | G22: 0 | H22: 0 | I22: 0 | J22: 0 | K22: 210 | L22: =C22+D22+E22+F22+G22+H22+I22+J22+K22 -> 904.09 | M22: =K22-N22 -> 208.01 | N22: =L22-B22-F22 -> 1.99 | O22: 78.85
A23: 44703 | B23: 1219.7 | C23: 613 | D23: 185.1 | E23: =2.53+2.93 -> 5.46 | F23: 0 | G23: 0 | H23: 0 | I23: 0 | J23: 0 | K23: 450 | L23: =C23+D23+E23+F23+G23+H23+I23+J23+K23 -> 1253.56 | M23: =K23-N23 -> 416.14 | N23: =L23-B23-F23 -> 33.86 | O23: 76.97
A24: 44704 | B24: 220.6 | C24: 126.6 | D24: 15.2 | E24: 0 | F24: 0 | G24: 0 | H24: 0 | I24: 0 | J24: 0 | K24: 80 | L24: =C24+D24+E24+F24+G24+H24+I24+J24+K24 -> 221.8 | M24: =K24-N24 -> 78.8 | N24: =L24-B24-F24 -> 1.2 | O24: 71.37
A25: 44705 | B25: 300.22 | C25: 187.72 | D25: 21.2 | E25: 4.59 | F25: 0 | G25: 0 | H25: 0 | I25: 0 | J25: 0 | K25: 90 | L25: =C25+D25+E25+F25+G25+H25+I25+J25+K25 -> 303.51 | M25: =K25-N25 -> 86.71 | N25: =L25-B25-F25 -> 3.29 | O25: 64.27
A26: 44706 | B26: 404.7 | C26: 277.2 | D26: 0 | E26: 0 | F26: 0 | G26: 0 | H26: 0 | I26: 0 | J26: 0 | K26: 130 | L26: =C26+D26+E26+F26+G26+H26+I26+J26+K26 -> 407.2 | M26: =K26-N26 -> 127.5 | N26: =L26-B26-F26 -> 2.5 | O26: 70.75
A27: 44707 | B27: 720.6 | C27: 417.18 | D27: 36.5 | E27: =8+2.7 -> 10.7 | F27: 0 | G27: 0 | H27: 0 | I27: 0 | J27: 0 | K27: 260 | L27: =C27+D27+E27+F27+G27+H27+I27+J27+K27 -> 724.38 | M27: =K27-N27 -> 256.22 | N27: =L27-B27-F27 -> 3.78 | O27: 79.87
A28: 44708 | B28: 1466.48 | C28: 814.18 | D28: 182.4 | E28: 0 | F28: 0 | G28: 0 | H28: 0 | I28: 0 | J28: 0 | K28: 470 | L28: =C28+D28+E28+F28+G28+H28+I28+J28+K28 -> 1466.58 | M28: =K28-N28 -> 469.9 | N28: =L28-B28-F28 -> 0.1 | O28: =P28+25 -> 60.04 | P28: 35.04
A29: 44709 | B29: 1635.56 | C29: 1059.2 | D29: 66.9 | E29: 0 | F29: 0 | G29: 0 | H29: 0 | I29: 0 | J29: 0 | K29: 510 | L29: =C29+D29+E29+F29+G29+H29+I29+J29+K29 -> 1636.1 | M29: =K29-N29 -> 509.46 | N29: =L29-B29-F29 -> 0.54 | O29: 71.04
A30: 44710 | B30: 1100.48 | C30: 673.6 | D30: 67.8 | E30: 0 | F30: 0 | G30: 0 | H30: 0 | I30: 0 | J30: 0 | K30: 360 | L30: =C30+D30+E30+F30+G30+H30+I30+J30+K30 -> 1101.4 | M30: =K30-N30 -> 359.08 | N30: =L30-B30-F30 -> 0.92 | O30: 85
A31: 44711 | L31: =C31+D31+E31+F31+G31+H31+I31+J31+K31 -> 0 | M31: =K31-N31 -> 0 | N31: =L31-B31-F31 -> 0
A32: 44712 | B32: 357.55 | C32: 287.95 | D32: 17.9 | H32: 18.9 | K32: 40 | L32: =C32+D32+E32+F32+G32+H32+I32+J32+K32 -> 364.75 | M32: =K32-N32 -> 32.8 | N32: =L32-B32-F32 -> 7.2 | O32: 77.8
A33: =SUM(Junho!B33) -> 0 | L33: =SUM(L2:L32) -> 15288.66 | M33: =SUM(M2:M32) -> 4945.77 | N33: =SUM(N2:N32) -> 145.74

Sheet Junho
B1: FECHO DO DIA | C1: SALT PAY | D1: SANTANDER | E1: GASTOS C/RECIBO | F1: GASTOS S/RECIBO | G1: GLOVO | H1: UBER EATS | I1: VOLUP | J1: BOLT | K1: NUMERARIO | L1: TOTAL | M1: DEPOSITO | N1: EXTRA | O1: FUNDO CAIXA
A2: 44713 | B2: 696.62 | C2: 453.08 | D2: 82.5 | E2: 0 | F2: 0 | G2: 0 | H2: 0 | I2: 0 | J2: 0 | K2: 170 | L2: =C2+D2+E2+F2+G2+H2+I2+J2+K2 -> 705.58 | M2: =K2-N2 -> 161.04 | N2: =L2-B2-F2 -> 8.96 | O2: 83.55
A3: 44714 | B3: 546.7 | C3: 343.1 | D3: 43.5 | E3: 0 | F3: 0 | G3: 0 | H3: 0 | I3: 0 | J3: 0 | K3: 165 | L3: =C3+D3+E3+F3+G3+H3+I3+J3+K3 -> 551.6 | M3: =K3-N3 -> 160.1 | N3: =L3-B3-F3 -> 4.9 | O3: 86.59
A4: 44715 | B4: 755.7 | C4: 342.1 | D4: 132.38 | E4: 0 | F4: 0 | G4: 37.8 | H4: 47.8 | I4: 0 | J4: 0 | K4: 235 | L4: =C4+D4+E4+F4+G4+H4+I4+J4+K4 -> 795.08 | M4: =K4-N4 -> 195.62 | N4: =L4-B4-F4 -> 39.38 | O4: 0
A5: 44716 | B5: 1609.99 | C5: 929.61 | D5: 200.1 | E5: =1.72+56.35 -> 58.07 | F5: 0 | G5: 0 | H5: 0 | I5: 0 | J5: 0 | K5: 430 | L5: =C5+D5+E5+F5+G5+H5+I5+J5+K5 -> 1617.78 | M5: =K5-N5 -> 422.21 | N5: =L5-B5-F5 -> 7.79 | O5: 83.76
A6: 44717 | B6: 1349.52 | C6: 844.46 | D6: 104 | E6: 0 | F6: 0 | G6: 0 | H6: 0 | I6: 0 | J6: 0 | K6: 410 | L6: =C6+D6+E6+F6+G6+H6+I6+J6+K6 -> 1358.46 | M6: =K6-N6 -> 401.06 | N6: =L6-B6-F6 -> 8.94 | O6: 84.06
A7: 44718 | B7: 0 | C7: 0 | D7: 0 | E7: 0 | F7: 0 | G7: 0 | H7: 0 | I7: 0 | J7: 0 | K7: 0 | L7: =C7+D7+E7+F7+G7+H7+I7+J7+K7 -> 0 | M7: =K7-N7 -> 0 | N7: =L7-B7-F7 -> 0 | O7: 0
A8: 44719 | B8: 403.9 | C8: 201.7 | D8: 49 | E8: 9.6 | F8: 0 | G8: 0 | H8: 0 | I8: 0 | J8: 0 | K8: 145 | L8: =C8+D8+E8+F8+G8+H8+I8+J8+K8 -> 405.3 | M8: =K8-N8 -> 143.6 | N8: =L8-B8-F8 -> 1.4 | O8: 83.7
A9: 44720 | B9: 310.2 | C9: 270 | D9: 3.8 | E9: 0 | F9: 0 | G9: 0 | H9: 0 | I9: 0 | J9: 0 | K9: 40 | L9: =C9+D9+E9+F9+G9+H9+I9+J9+K9 -> 313.8 | M9: =K9-N9 -> 36.4 | N9: =L9-B9-F9 -> 3.6 | O9: 80.2
A10: 44721 | B10: 481.64 | C10: 313.44 | D10: 14.4 | E10: 0 | F10: 0 | G10: 0 | H10: 0 | I10: 0 | J10: 0 | K10: 155 | L10: =C10+D10+E10+F10+G10+H10+I10+J10+K10 -> 482.84 | M10: =K10-N10 -> 153.8 | N10: =L10-B10-F10 -> 1.2 | O10: 84.2
A11: 44722 | B11: 1388.99 | C11: 866.91 | D11: 87.5 | E11: 0 | F11: 0 | G11: 0 | H11: 0 | I11: 0 | J11: 0 | K11: 445 | L11: =C11+D11+E11+F11+G11+H11+I11+J11+K11 -> 1399.41 | M11: =K11-N11 -> 434.58 | N11: =L11-B11-F11 -> 10.42 | O11: 83.73
A12: 44723 | B12: 1438.15 | C12: 852.85 | D12: 101.5 | E12: 0 | F12: 0 | G12: 0 | H12: 0 | I12: 0 | J12: 0 | K12: 510 | L12: =C12+D12+E12+F12+G12+H12+I12+J12+K12 -> 1464.35 | M12: =K12-N12 -> 483.8 | N12: =L12-B12-F12 -> 26.2 | O12: 86.72
A13: 44724 | B13: 1268.28 | C13: 791.08 | D13: 92.8 | E13: 17.79 | F13: 0 | G13: 0 | H13: 18.9 | I13: 0 | J13: 0 | K13: 350 | L13: =C13+D13+E13+F13+G13+H13+I13+J13+K13 -> 1270.57 | M13: =K13-N13 -> 347.71 | N13: =L13-B13-F13 -> 2.29 | O13: 78.02
A14: 44725 | B14: 0 | C14: 0 | D14: 0 | E14: 0 | F14: 0 | G14: 0 | H14: 0 | I14: 0 | J14: 0 | K14: 0 | L14: 0 | M14: 0 | N14: 0 | O14: 0
A15: 44726 | B15: 405.24 | C15: 204.4 | D15: 23.8 | E15: 0 | F15: 0 | G15: 0 | H15: 0 | I15: 0 | J15: 0 | K15: 180 | L15: =C15+D15+E15+F15+G15+H15+I15+J15+K15 -> 408.2 | M15: =K15-N15 -> 177.04 | N15: =L15-B15-F15 -> 2.96 | O15: 82.09
A16: 44727 | B16: 161.4 | C16: 92.2 | D16: 3.8 | E16: 0 | F16: 0 | G16: 0 | H16: 0 | I16: 0 | J16: 0 | K16: 65 | L16: =C16+D16+E16+F16+G16+H16+I16+J16+K16 -> 161 | M16: =K16-N16 -> 65.4 | N16: =L16-B16-F16 -> -0.4 | O16: 83.04
A17: 44728 | B17: 729.5 | C17: 393 | D17: 59.9 | E17: 0 | F17: 0 | G17: 0 | H17: 0 | I17: 0 | J17: 0 | K17: 315 | L17: =C17+D17+E17+F17+G17+H17+I17+J17+K17 -> 767.9 | M17: =K17-N17 -> 276.6 | N17: =L17-B17-F17 -> 38.4 | O17: 80.14
A18: 44729 | B18: 937.4 | C18: 521.3 | D18: 83.4 | E18: 11.22 | F18: 0 | G18: 0 | H18: 0 | I18: 0 | J18: 0 | K18: 340 | L18: =C18+D18+E18+F18+G18+H18+I18+J18+K18 -> 955.92 | M18: =K18-N18 -> 321.48 | N18: =L18-B18-F18 -> 18.52 | O18: 82.58
A19: 44730 | B19: 1100.6 | C19: 608.6 | D19: 97.3 | E19: 0 | F19: 0 | G19: 0 | H19: 0 | I19: 0 | J19: 0 | K19: 415 | L19: =C19+D19+E19+F19+G19+H19+I19+J19+K19 -> 1120.9 | M19: =K19-N19 -> 394.7 | N19: =L19-B19-F19 -> 20.3 | O19: 81.6
A20: 44731 | B20: 1117.16 | C20: 689.38 | D20: 63.5 | E20: 1 | F20: 0 | G20: 0 | H20: 0 | I20: 0 | J20: 0 | K20: 365 | L20: =C20+D20+E20+F20+G20+H20+I20+J20+K20 -> 1118.88 | M20: =K20-N20 -> 363.28 | N20: =L20-B20-F20 -> 1.72 | O20: 84.51
A21: 44732 | B21: 0 | C21: 0 | D21: 0 | E21: 0 | F21: 0 | G21: 0 | H21: 0 | I21: 0 | J21: 0 | K21: 0 | L21: =C21+D21+E21+F21+G21+H21+I21+J21+K21 -> 0 | M21: =K21-N21 -> 0 | N21: =L21-B21-F21 -> 0 | O21: 0
A22: 44733 | B22: 212.4 | C22: 106.8 | D22: 11.1 | E22: 0 | F22: 0 | G22: 18.9 | H22: 0 | I22: 0 | J22: 0 | K22: 75 | L22: =C22+D22+E22+F22+G22+H22+I22+J22+K22 -> 211.8 | M22: =K22-N22 -> 75.6 | N22: =L22-B22-F22 -> -0.6 | O22: 84.58
A23: 44734 | B23: 500.1 | C23: 278.8 | D23: 37.4 | E23: 0 | F23: 0 | G23: 0 | H23: 0 | I23: 0 | J23: 0 | K23: 185 | L23: =C23+D23+E23+F23+G23+H23+I23+J23+K23 -> 501.2 | M23: =K23-N23 -> 183.9 | N23: =L23-B23-F23 -> 1.1 | O23: 79.85
A24: 44735 | B24: 354.48 | C24: 165.18 | D24: 0 | E24: 0 | F24: 0 | G24: 0 | H24: 0 | I24: 0 | J24: 0 | K24: 190 | L24: =C24+D24+E24+F24+G24+H24+I24+J24+K24 -> 355.18 | M24: =K24-N24 -> 189.3 | N24: =L24-B24-F24 -> 0.7 | O24: 81.95
A25: 44736 | B25: 934.38 | C25: 505.28 | D25: 123.9 | E25: 0 | F25: 0 | G25: 0 | H25: 19.9 | I25: 0 | J25: 0 | K25: 305 | L25: =C25+D25+E25+F25+G25+H25+I25+J25+K25 -> 954.08 | M25: =K25-N25 -> 285.3 | N25: =L25-B25-F25 -> 19.7 | O25: 82.2
A26: 44737 | B26: 1514.32 | C26: 848.64 | D26: 119.48 | E26: 0 | F26: 0 | G26: 0 | H26: 36.9 | I26: 0 | J26: 0 | K26: 500 | L26: =C26+D26+E26+F26+G26+H26+I26+J26+K26 -> 1505.02 | M26: =K26-N26 -> 509.3 | N26: =L26-B26-F26 -> -9.3 | O26: 86.18
... A28: 44739 | B28: 0 | C28: 0 | D28: 0 | E28: 0 | F28: 0 | G28: 0 | H28: 0 | I28: 0 | J28: 0 | K28: 0 | L28: =C28+D28+E28+F28+G28+H28+I28+J28+K28 -> 0 | M28: =K28-N28 -> 0 | N28: =L28-B28-F28 -> 0 | O28: 0
A29: 44740 | B29: 576.8 | C29: 319.1 | D29: 40.2 | E29: 0 | F29: 0 | G29: 0 | H29: 0 | I29: 0 | J29: 0 | K29: 220 | L29: =C29+D29+E29+F29+G29+H29+I29+J29+K29 -> 579.3 | M29: =K29-N29 -> 217.5 | N29: =L29-B29-F29 -> 2.5 | O29: 81.32 | P29: 35.04
A30: 44741 | B30: 525.8 | C30: 269.2 | D30: 52.3 | E30: 0 | F30: 0 | G30: 0 | H30: 0 | I30: 0 | J30: 0 | K30: 205 | L30: =C30+D30+E30+F30+G30+H30+I30+J30+K30 -> 526.5 | M30: =K30-N30 -> 204.3 | N30: =L30-B30-F30 -> 0.7 | O30: 80.27
A31: 44742 | B31: 542.14 | C31: 334.94 | D31: 33.1 | E31: 0 | F31: 0 | G31: 0 | H31: 0 | I31: 0 | J31: 0 | K31: 175 | L31: =C31+D31+E31+F31+G31+H31+I31+J31+K31 -> 543.04 | M31: =K31-N31 -> 174.1 | N31: =L31-B31-F31 -> 0.9 | O31: 80.68
L32: =C32+D32+E32+F32+G32+H32+I32+J32+K32 -> 0 | M32: =K32-N32 -> 0 | N32: =L32-B32-F32 -> 0 | O32: 0
B33: 0 | C33: 0 | D33: 0 | H33: 0 | K33: 0 | L33: =C33+D33+E33+F33+G33+H33+I33+J33+K33 -> 0 | M33: =K33-N33 -> 0 | N33: =L33-B33-F33 -> 0 | O33: 0
A34: TOTAL | L34: =SUM(L2:L33) -> 21314.05 | M34: =L34-N34 -> 21098.42 | N34: =SUM(N2:N33) -> 215.63 | Q34: =L34/26 -> 819.77115 | R34: /dia

Sheet Julho
B1: FECHO DO DIA | C1: SALT PAY | D1: SANTANDER | E1: GASTOS C/RECIBO | F1: GASTOS S/RECIBO | G1: GLOVO | H1: UBER EATS | I1: VOLUP | J1: BOLT | K1: Transf. Bancária | L1: NUMERARIO | M1: TOTAL | N1: DEPOSITO | O1: EXTRA | P1: FUNDO CAIXA
A2: 44743 | B2: 763.46 | C2: 459.56 | D2: 38.4 | E2: 0 | F2: 0 | G2: 0 | H2: 0 | I2: 0 | J2: 0 | L2: 265 | M2: =C2+D2+E2+F2+G2+H2+I2+J2+L2 -> 762.96 | N2: =L2-O2 -> 265.5 | O2: =M2-B2-F2 -> -0.5 | P2: 80.27
A3: 44744 | B3: 1076.44 | C3: 613.64 | D3: 116.3 | E3: 0.99 | F3: 0 | G3: 0 | H3: 0 | I3: 0 | J3: 0 | L3: 335 | M3: =C3+D3+E3+F3+G3+H3+I3+J3+L3 -> 1065.93 | N3: =L3-O3 -> 345.51 | O3: =M3-B3-F3 -> -10.51 | P3: 81.42
A4: 44745 | B4: 1300.2 | C4: 829.44 | D4: 58.84 | E4: 11.98 | F4: 0 | G4: 0 | H4: 0 | I4: 0 | J4: 0 | L4: 400 | M4: =C4+D4+E4+F4+G4+H4+I4+J4+L4 -> 1300.26 | N4: =L4-O4 -> 399.94 | O4: =M4-B4-F4 -> 0.06 | P4: 71.35
A5: 44746 | B5: 0 | C5: 0 | D5: 0 | E5: 0 | F5: 0 | G5: 0 | H5: 0 | I5: 0 | J5: 0 | L5: 0 | M5: 0 | N5: 0 | O5: 0
A6: 44747 | B6: 605 | C6: 398 | D6: 13.6 | E6: 0 | F6: 0 | G6: 36.9 | H6: 0 | I6: 0 | J6: 0 | L6: 160 | M6: =C6+D6+E6+F6+G6+H6+I6+J6+L6 -> 608.5 | N6: =L6-O6 -> 156.5 | O6: =M6-B6-F6 -> 3.5 | P6: 70.76
A7: 44748 | B7: 1013.2 | C7: 591.2 | D7: 45.7 | E7: 0 | F7: 0 | G7: 0 | H7: 0 | I7: 0 | J7: 0 | L7: 380 | M7: =C7+D7+E7+F7+G7+H7+I7+J7+L7 -> 1016.9 | N7: =L7-O7 -> 376.3 | O7: =M7-B7-F7 -> 3.7 | P7: 71.1
A8: 44749 | B8: 1400.45 | C8: 839.86 | D8: 108.4 | E8: 0 | F8: 0 | G8: 0 | H8: 0 | I8: 0 | J8: 0 | L8: 450 | M8: =C8+D8+E8+F8+G8+H8+I8+J8+L8 -> 1398.26 | N8: =L8-O8 -> 452.19 | O8: =M8-B8-F8 -> -2.19 | P8: 74
A9: 44750 | B9: 1682.19 | C9: 1023.19 | D9: 101.2 | E9: 0 | F9: 0 | G9: 0 | H9: 37.8 | I9: 0 | J9: 0 | L9: 525 | M9: =C9+D9+E9+F9+G9+H9+I9+J9+L9 -> 1687.19 | N9: =L9-O9 -> 520 | O9: =M9-B9-F9 -> 5 | P9: 74.69
A10: 44751 | B10: 1836.79 | C10: 1185.39 | D10: 165 | E10: 0 | F10: 0 | G10: 0 | H10: 0 | I10: 0 | J10: 0 | L10: 500 | M10: =C10+D10+E10+F10+G10+H10+I10+J10+L10 -> 1850.39 | N10: =L10-O10 -> 486.4 | O10: =M10-B10-F10 -> 13.6 | P10: 74
A11: 44752 | B11: 1206.1 | C11: 781.32 | D11: 67.4 | E11: 7.21 | F11: 0 | G11: 0 | H11: 0 | I11: 0 | J11: 0 | L11: 350 | M11: =C11+D11+E11+F11+G11+H11+I11+J11+L11 -> 1205.93 | N11: =L11-O11 -> 350.17 | O11: =M11-B11-F11 -> -0.17 | P11: 90.61
A12: 44753 | B12: 0 | E12: 0 | F12: 0 | G12: 0 | H12: 0 | I12: 0 | J12: 0 | L12: 0 | M12: =C12+D12+E12+F12+G12+H12+I12+J12+L12 -> 0 | N12: =L12-O12 -> 0 | O12: =M12-B12-F12 -> 0
A13: 44754 | B13: 1537.05 | C13: 835.85 | D13: 182.7 | E13: 0 | F13: 0 | G13: 0 | H13: 0 | I13: 0 | J13: 0 | L13: 525 | M13: =C13+D13+E13+F13+G13+H13+I13+J13+L13 -> 1543.55 | N13: =L13-O13 -> 518.5 | O13: =M13-B13-F13 -> 6.5 | P13: 90.04
A14: 44755 | B14: 1401.38 | C14: 655.44 | D14: 119.6 | E14: 0 | F14: 0 | G14: 0 | H14: 0 | I14: 0 | J14: 0 | L14: 625 | M14: =C14+D14+E14+F14+G14+H14+I14+J14+L14 -> 1400.04 | N14: =L14-O14 -> 626.34 | O14: =M14-B14-F14 -> -1.34 | P14: 83.45
A15: 44756 | B15: 1380.94 | C15: 769.54 | D15: 53.6 | E15: 0 | F15: 0 | G15: 0 | H15: 0 | I15: 0 | J15: 0 | K15: 156.8 | L15: 400 | M15: =C15+D15+E15+F15+G15+H15+I15+J15+L15+K15 -> 1379.94 | N15: =L15-O15 -> 401 | O15: =M15-B15-F15 -> -1 | P15: 78.81
A16: 44757 | B16: 1250.85 | C16: 719.25 | D16: 48.8 | E16: 0 | F16: 0 | G16: 0 | H16: 0 | I16: 0 | J16: 0 | L16: 495 | M16: =C16+D16+E16+F16+G16+H16+I16+J16+L16 -> 1263.05 | N16: =L16-O16 -> 482.8 | O16: =M16-B16-F16 -> 12.2 | P16: 80.2
A17: 44758 | B17: 1834.2 | C17: 939.16 | D17: 161 | E17: 12 | F17: 0 | G17: 0 | H17: 103.5 | I17: 0 | J17: 0 | L17: 618.34 | M17: =C17+D17+E17+F17+G17+H17+I17+J17+L17 -> 1834 | N17: =L17-O17 -> 618.54 | O17: =M17-B17-F17 -> -0.2 | P17: =46.67+45 -> 91.67
A18: 44759 | B18: 1630 | C18: 987.35 | D18: 108.5 | E18: 0 | F18: 0 | G18: 0 | H18: 19.9 | I18: 0 | J18: 0 | L18: 520 | M18: =C18+D18+E18+F18+G18+H18+I18+J18+L18 -> 1635.75 | N18: =L18-O18 -> 514.25 | O18: =M18-B18-F18 -> 5.75 | P18: 85.29
A19: 44760 | B19: 0 | C19: 0 | D19: 0 | E19: 0 | F19: 0 | G19: 0 | H19: 0 | I19: 0 | J19: 0 | L19: 0 | M19: 0 | N19: 0 | O19: =M19-B19-F19 -> 0
A20: 44761 | B20: 957.54 | C20: 602.3 | D20: 57.04 | E20: 0 | F20: 0 | G20: 0 | H20: 0 | I20: 0 | J20: 0 | L20: 300 | M20: =C20+D20+E20+F20+G20+H20+I20+J20+L20 -> 959.34 | N20: =L20-O20 -> 298.2 | O20: =M20-B20-F20 -> 1.8 | P20: 83.35
A21: 44762 | B21: 963.38 | C21: 531.18 | D21: 43.5 | E21: 0 | F21: 0 | G21: 0 | H21: 0 | I21: 0 | J21: 0 | L21: 385 | M21: =C21+D21+E21+F21+G21+H21+I21+J21+L21 -> 959.68 | N21: =L21-O21 -> 388.7 | O21: =M21-B21-F21 -> -3.7 | P21: 74
A22: 44763 | B22: 1070.5 | C22: 582.95 | D22: 104 | E22: 0 | F22: 0 | G22: 0 | H22: 0 | I22: 0 | J22: 0 | L22: 385 | M22: =C22+D22+E22+F22+G22+H22+I22+J22+L22 -> 1071.95 | N22: =L22-O22 -> 383.55 | O22: =M22-B22-F22 -> 1.45 | P22: 72.69
A23: 44764 | B23: 1180.88 | C23: =793.78-D23 -> 723.98 | D23: 69.8 | E23: 0 | F23: 0 | G23: 0 | H23: 37.8 | I23: 0 | J23: 0 | L23: 350 | M23: =C23+D23+E23+F23+G23+H23+I23+J23+L23 -> 1181.58 | N23: =L23-O23 -> 349.3 | O23: =M23-B23-F23 -> 0.7 | P23: 75.52
A24: 44765 | B24: 1611 | C24: 881.9 | D24: 79.5 | E24: 0 | F24: 0 | G24: 0 | H24: 18.9 | I24: 0 | J24: 0 | L24: 630 | M24: =C24+D24+E24+F24+G24+H24+I24+J24+L24 -> 1610.3 | N24: =L24-O24 -> 630.7 | O24: =M24-B24-F24 -> -0.7 | P24: 73.6
A25: 44766 | B25: 1291.56 | C25: 727.34 | D25: 112.3 | E25: 0 | F25: 0 | G25: 0 | H25: 0 | I25: 0 | J25: 0 | L25: 460 | M25: =C25+D25+E25+F25+G25+H25+I25+J25+L25 -> 1299.64 | N25: =L25-O25 -> 451.92 | O25: =M25-B25-F25 -> 8.08 | P25: 74.25
A26: 44767 | B26: 0 | C26: 0 | D26: 0 | E26: 0 | F26: 0 | G26: 0 | H26: 0 | I26: 0 | J26: 0 | L26: 0 | M26: =C26+D26+E26+F26+G26+H26+I26+J26+L26 -> 0 | N26: =L26-O26 -> 0 | O26: =M26-B26-F26 -> 0
A27: 44768 | B27: 1194.13 | C27: 621.84 | D27: 41.2 | E27: 0 | F27: 0 | G27: 0 | H27: 0 | I27: 0 | J27: 0 | K27: 195.99 | L27: 335 | M27: =C27+D27+E27+F27+G27+H27+I27+J27+L27+K27 -> 1194.03 | N27: =L27-O27 -> 335.1 | O27: =M27-B27-F27 -> -0.1 | P27: 76.23
A28: 44769 | B28: 905.52 | C28: 533.72 | D28: 54.8 | E28: 0 | F28: 0 | G28: 0 | H28: 18.9 | I28: 0 | J28: 0 | L28: 300 | M28: =C28+D28+E28+F28+G28+H28+I28+J28+L28 -> 907.42 | N28: =L28-O28 -> 298.1 | O28: =M28-B28-F28 -> 1.9 | P28: 70.75
A29: 44770 | B29: 679.9 | C29: 333.8 | D29: 67.7 | E29: 0 | F29: 0 | G29: 0 | H29: 0 | I29: 0 | J29: 0 | L29: 275 | M29: =C29+D29+E29+F29+G29+H29+I29+J29+L29 -> 676.5 | N29: =L29-O29 -> 278.4 | O29: =M29-B29-F29 -> -3.4 | P29: 70.33 | Q29: 35.04
A30: 44771 | B30: 1340.5 | C30: 843.16 | D30: 160.4 | E30: 0 | F30: 0 | G30: 0 | H30: 0 | I30: 0 | J30: 0 | L30: 350 | M30: =C30+D30+E30+F30+G30+H30+I30+J30+L30 -> 1353.56 | N30: =L30-O30 -> 336.94 | O30: =M30-B30-F30 -> 13.06 | P30: 75.88
A31: 44772 | B31: 1723.62 | C31: 938.72 | D31: 112.9 | E31: 0 | F31: 0 | G31: 0 | H31: 46.8 | I31: 0 | J31: 0 | L31: 625 | M31: =C31+D31+E31+F31+G31+H31+I31+J31+L31 -> 1723.42 | N31: =L31-O31 -> 625.2 | O31: =M31-B31-F31 -> -0.2 | P31: 76.2
A32: 44773 | B32: 1543.92 | C32: 1026.16 | D32: 73 | E32: 0 | F32: 0 | G32: 0 | H32: 0 | I32: 0 | J32: 0 | L32: 440 | M32: =C32+D32+E32+F32+G32+H32+I32+J32+L32 -> 1539.16 | N32: =L32-O32 -> 444.76 | O32: =M32-B32-F32 -> -4.76 | P32: 79.46
B33: 0 | C33: 0 | D33: 0 | E33: 0 | F33: 0 | G33: 0 | H33: 0 | I33: 0 | J33: 0 | L33: 0 | M33: =C33+D33+E33+F33+G33+H33+I33+J33+L33 -> 0 | N33: =L33-O33 -> 0 | O33: =M33-B33-F33 -> 0
A34: TOTAL | M34: =SUM(M2:M33) -> 34429.23 | N34: =M34-O34 -> 34380.7 | O34: =SUM(O2:O33) -> 48.53 | R34: =M34/26 -> 1324.2012 | S34: /dia

Sheet Agosto
B1: FECHO DO DIA | C1: SALT PAY | D1: SANTANDER | E1: GASTOS C/RECIBO | F1: GASTOS S/RECIBO | G1: GLOVO | H1: UBER EATS | I1: VOLUP | J1: BOLT | K1: Transf. Bancária | L1: NUMERARIO | M1: TOTAL | N1: DEPOSITO | O1: EXTRA | P1: FUNDO CAIXA
A2: 44774 | M2: =C2+D2+E2+F2+G2+H2+I2+J2+L2 -> 0 | N2: =L2-O2 -> 0 | O2: =M2-B2-F2 -> 0 | P2: 79.46
A3: 44775 | B3: 755.54 | C3: 430.74 | D3: 11.4 | E3: 0 | F3: 0 | G3: 0 | H3: 0 | I3: 0 | J3: 0 | K3: 0 | L3: 310 | M3: =C3+D3+E3+F3+G3+H3+I3+J3+L3 -> 752.14 | N3: =L3-O3 -> 313.4 | O3: =M3-B3-F3 -> -3.4 | P3: 82.93 | Q3: 33 euro quilos melhor
A4: 44776 | B4: 1087 | C4: 642.52 | D4: 43.2 | L4: 400 | M4: =C4+D4+E4+F4+G4+H4+I4+J4+L4+K4 -> 1085.72 | N4: =L4-O4 -> 401.28 | O4: =M4-B4-F4 -> -1.28 | P4: 71.35
A5: 44777 | B5: 965.21 | C5: 532.86 | D5: 35.8 | L5: 398.72 | M5: =C5+D5+E5+F5+G5+H5+I5+J5+L5+K5 -> 967.38 | N5: =L5-O5 -> 396.55 | O5: =M5-B5-F5 -> 2.17 | P5: =26.65+50 -> 76.65
A6: 44778 | B6: 871.88 | C6: 347.28 | D6: 89 | G6: 18.9 | H6: 37.8 | L6: 440 | M6: =C6+D6+E6+F6+G6+H6+I6+J6+L6+K6 -> 932.98 | N6: =L6-O6 -> 378.9 | O6: =M6-B6-F6 -> 61.1 | P6: 75.71
A7: 44779 | B7: 1079.92 | C7: 660.52 | D7: 39.2 | L7: 382.22 | M7: =C7+D7+E7+F7+G7+H7+I7+J7+L7+K7 -> 1081.94 | N7: =L7-O7 -> 380.2 | O7: =M7-B7-F7 -> 2.02 | P7: =50+37.93 -> 87.93 | Q7: 29.37
A8: 44780 | B8: 1011.56 | C8: 649.16 | D8: 51.5 | L8: 310 | M8: =C8+D8+E8+F8+G8+H8+I8+J8+L8+K8 -> 1010.66 | N8: =L8-O8 -> 310.9 | O8: =M8-B8-F8 -> -0.9 | P8: 86.63
A9: 44781 | B9: 0 | C9: 0 | D9: 0 | E9: 0 | F9: 0 | G9: 0 | H9: 0 | I9: 0 | J9: 0 | K9: 0 | L9: 0 | M9: 0 | N9: 0 | O9: 0
A10: 44782 | B10: 957.66 | C10: 567.56 | D10: 19 | H10: 56.7 | L10: 315 | M10: =C10+D10+E10+F10+G10+H10+I10+J10+L10+K10 -> 958.26 | N10: =L10-O10 -> 314.4 | O10: =M10-B10-F10 -> 0.6 | P10: 86.12
A11: 44783 | B11: 1146.49 | C11: 732.99 | D11: 73.4 | L11: 340 | M11: =C11+D11+E11+F11+G11+H11+I11+J11+L11+K11 -> 1146.39 | N11: =L11-O11 -> 340.1 | O11: =M11-B11-F11 -> -0.1 | P11: 89.22
A12: 44784 | B12: 1002.65 | C12: 434.58 | D12: 61.7 | L12: 510 | M12: =C12+D12+E12+F12+G12+H12+I12+J12+L12+K12 -> 1006.28 | N12: =L12-O12 -> 506.37 | O12: =M12-B12-F12 -> 3.63 | P12: 87.52 | Q12: 27,83 euro/quilos ok | S12: o resultado muda de acordo com a pastelaria produzida e não vendida
A13: 44785 | B13: 1366.1 | C13: 757.22 | D13: 92.1 | H13: 18.9 | L13: 520 | M13: =C13+D13+E13+F13+G13+H13+I13+J13+L13+K13 -> 1388.22 | N13: =L13-O13 -> 497.88 | O13: =M13-B13-F13 -> 22.12
A14: 44786 | B14: 1404.78 | C14: 796.28 | D14: 74.9 | L14: 530 | M14: =C14+D14+E14+F14+G14+H14+I14+J14+L14+K14 -> 1401.18 | N14: =L14-O14 -> 533.6 | O14: =M14-B14-F14 -> -3.6 | P14: 100.72
A15: 44787 | B15: 1300.92 | C15: 724.74 | D15: 63.9 | L15: 515 | M15: =C15+D15+E15+F15+G15+H15+I15+J15+L15+K15 -> 1303.64 | N15: =L15-O15 -> 512.28 | O15: =M15-B15-F15 -> 2.72 | P15: 98.62
A16: 44788 | B16: 1253.9 | C16: 635.2 | D16: 78.6 | L16: 540 | M16: =C16+D16+E16+F16+G16+H16+I16+J16+L16+K16 -> 1253.8 | N16: =L16-O16 -> 540.1 | O16: =M16-B16-F16 -> -0.1 | P16: 98.87
A17: 44789 | B17: 0 | C17: 0 | D17: 0 | L17: 0 | M17: =C17+D17+E17+F17+G17+H17+I17+J17+L17+K17 -> 0 | N17: =L17-O17 -> 0 | O17: =M17-B17-F17 -> 0
A18: 44790 | B18: 762.34 | C18: 402.98 | D18: 52.4 | L18: 310 | M18: =C18+D18+E18+F18+G18+H18+I18+J18+L18+K18 -> 765.38 | N18: =L18-O18 -> 306.96 | O18: =M18-B18-F18 -> 3.04 | P18: 84.77
A19: 44791 | B19: 1119.84 | C19: 652.36 | D19: 38.4 | L19: 450 | M19: =C19+D19+E19+F19+G19+H19+I19+J19+L19+K19 -> 1140.76 | N19: =L19-O19 -> 429.08 | O19: =M19-B19-F19 -> 20.92 | P19: 83.57
A20: 44792 | B20: 1517.72 | C20: 799.28 | D20: 117.1 | H20: 27.9 | L20: 574.71 | M20: =C20+D20+E20+F20+G20+H20+I20+J20+L20+K20 -> 1518.99 | N20: =L20-O20 -> 573.44 | O20: =M20-B20-F20 -> 1.27 | P20: 78.28
A21: 44793 | B21: 1400.8 | C21: 850.2 | D21: 71.02 | J21: 27.9 | L21: 452.89 | M21: =C21+D21+E21+F21+G21+H21+I21+J21+L21+K21 -> 1402.01 | N21: =L21-O21 -> 451.68 | O21: =M21-B21-F21 -> 1.21 | P21: 71.17
A22: 44794 | B22: 1142.68 | C22: 649.3 | D22: 43.3 | L22: 440 | M22: =C22+D22+E22+F22+G22+H22+I22+J22+L22+K22 -> 1132.6 | N22: =L22-O22 -> 450.08 | O22: =M22-B22-F22 -> -10.08 | P22: 78.62
A23: 44795 | B23: 0 | C23: 0 | D23: 0 | L23: 0 | M23: 0 | N23: 0 | O23: 0 | P23: 0
A24: 44796 | B24: 1035.55 | C24: 613.25 | D24: 36.8 | L24: 430 | M24: =C24+D24+E24+F24+G24+H24+I24+J24+L24+K24 -> 1080.05 | N24: =L24-O24 -> 385.5 | O24: =M24-B24-F24 -> 44.5 | P24: 84.41
A25: 44797 | B25: 576.06 | C25: 317.64 | D25: 24.4 | L25: 240 | M25: =C25+D25+E25+F25+G25+H25+I25+J25+L25+K25 -> 582.04 | N25: =L25-O25 -> 234.02 | O25: =M25-B25-F25 -> 5.98 | P25: 81.32
A26: 44798 | B26: 887.72 | C26: 486.8 | D26: 11.4 | L26: 390 | M26: =C26+D26+E26+F26+G26+H26+I26+J26+L26+K26 -> 888.2 | N26: =L26-O26 -> 389.52 | O26: =M26-B26-F26 -> 0.48 | P26: 83.32
A27: 44799 | B27: 1189.92 | C27: 685.08 | D27: 91.64 | L27: 410 | M27: =C27+D27+E27+F27+G27+H27+I27+J27+L27+K27 -> 1186.72 | N27: =L27-O27 -> 413.2 | O27: =M27-B27-F27 -> -3.2 | P27: 86.72
A28: 44800 | B28: 1482.84 | C28: 877.86 | D28: 141 | L28: 465 | M28: =C28+D28+E28+F28+G28+H28+I28+J28+L28+K28 -> 1483.86 | N28: =L28-O28 -> 463.98 | O28: =M28-B28-F28 -> 1.02 | P28: 85.92
A29: 44801 | B29: 1360.2 | C29: 693.1 | D29: 139.2 | H29: 55.8 | L29: 470 | M29: =C29+D29+E29+F29+G29+H29+I29+J29+L29+K29 -> 1358.1 | N29: =L29-O29 -> 472.1 | O29: =M29-B29-F29 -> -2.1 | P29: 84.22 | Q29: 35.04
A30: 44802 | B30: 0 | C30: 0 | D30: 0 | L30: 0 | M30: 0 | N30: 0 | O30: =M30-B30-F30 -> 0 | P30: 0
A31: 44803 | B31: 811.5 | C31: 427.14 | D31: 66 | L31: 320 | M31: =C31+D31+E31+F31+G31+H31+I31+J31+L31+K31 -> 813.14 | N31: =L31-O31 -> 318.36 | O31: =M31-B31-F31 -> 1.64 | P31: 82.82
A32: 44804 | B32: 1055.66 | C32: 573.21 | D32: 57.46 | H32: 18.9 | L32: 405 | M32: =C32+D32+E32+F32+G32+H32+I32+J32+L32+K32 -> 1054.57 | N32: =L32-O32 -> 406.09 | O32: =M32-B32-F32 -> -1.09 | P32: 80.57
M33: =C33+D33+E33+F33+G33+H33+I33+J33+L33+K33 -> 0 | N33: =L33-O33 -> 0 | O33: =M33-B33-F33 -> 0
A34: TOTAL | M34: =SUM(M2:M33) -> 28695.01 | N34: =M34-O34 -> 28546.44 | O34: =SUM(O2:O33) -> 148.57 | R34: =M34/26 -> 1103.6542 | S34: /dia
N36: =SUM(N26:N33) -> 2463.25
N37: 2158

Sheet Setembro
B1: FECHO DO DIA | C1: SALT PAY | D1: SANTANDER | E1: GASTOS C/RECIBO | F1: GASTOS S/RECIBO | G1: GLOVO | H1: UBER EATS | I1: VOLUP | J1: BOLT | K1: Transf. Bancária | L1: NUMERARIO | M1: TOTAL | N1: DEPOSITO | O1: EXTRA | P1: FUNDO CAIXA | R1: Num cert
A2: 44805 | B2: 800.88 | C2: 455.78 | D2: 109.3 | H2: 18.9 | L2: 220 | M2: =C2+D2+E2+F2+G2+H2+I2+J2+L2 -> 803.98 | N2: =L2-O2 -> 216.9 | O2: =M2-B2-F2 -> 3.1 | P2: 82.57
A3: 44806 | B3: 1035.27 | C3: 554.47 | D3: 102.6 | L3: 380 | M3: =C3+D3+E3+F3+G3+H3+I3+J3+L3 -> 1037.07 | N3: =L3-O3 -> 378.2 | O3: =M3-B3-F3 -> 1.8 | P3: 82.07
A4: 44807 | B4: 1138.1 | C4: 785.76 | D4: 58.36 | L4: 275 | M4: =C4+D4+E4+F4+G4+H4+I4+J4+L4+K4 -> 1119.12 | N4: =L4-O4 -> 293.98 | O4: =M4-B4-F4 -> -18.98 | P4: 83.07
A5: 44808 | B5: 1004.64 | C5: 601.44 | D5: 65.5 | H5: 37.8 | L5: 320.04 | M5: =C5+D5+E5+F5+G5+H5+I5+J5+L5+K5 -> 1024.78 | N5: =L5-O5 -> 299.9 | O5: =M5-B5-F5 -> 20.14 | P5: 83.11
A6: 44809 | B6: 0 | C6: 0 | D6: 0 | E6: 0 | F6: 0 | G6: 0 | H6: 0 | I6: 0 | J6: 0 | K6: 0 | L6: 0 | M6: 0 | N6: 0 | O6: =M6-B6-F6 -> 0
A7: 44810 | B7: 727.22 | C7: 410.74 | D7: 94.26 | L7: 225 | M7: =C7+D7+E7+F7+G7+H7+I7+J7+L7+K7 -> 730 | N7: =L7-O7 -> 222.22 | O7: =M7-B7-F7 -> 2.78 | P7: 80.66
A8: 44811 | B8: 528.63 | C8: 260.78 | D8: 24.9 | H8: 18.9 | L8: 225 | M8: =C8+D8+E8+F8+G8+H8+I8+J8+L8+K8 -> 529.58 | N8: =L8-O8 -> 224.05 | O8: =M8-B8-F8 -> 0.95 | P8: 80.61
A9: 44812 | B9: 625.4 | C9: 345.94 | D9: 47.46 | H9: 27.9 | L9: 205 | M9: =C9+D9+E9+F9+G9+H9+I9+J9+L9+K9 -> 626.3 | N9: =L9-O9 -> 204.1 | O9: =M9-B9-F9 -> 0.9 | P9: 80.21
A10: 44813 | B10: 856.66 | C10: 483.64 | D10: 53.7 | L10: 320.49 | M10: =C10+D10+E10+F10+G10+H10+I10+J10+L10+K10 -> 857.83 | N10: =L10-O10 -> 319.32 | O10: =M10-B10-F10 -> 1.17
A11: 44814 | B11: 1386.78 | C11: 787.48 | D11: 94.5 | L11: 545 | M11: =C11+D11+E11+F11+G11+H11+I11+J11+L11+K11 -> 1426.98 | N11: =L11-O11 -> 504.8 | O11: =M11-B11-F11 -> 40.2 | P11: 84.1
A12: 44815 | B12: 1632.97 | C12: 967.74 | D12: 89.3 | L12: 611.65 | M12: =C12+D12+E12+F12+G12+H12+I12+J12+L12+K12 -> 1668.69 | N12: =L12-O12 -> 575.93 | O12: =M12-B12-F12 -> 35.72 | P12: 85.75
A13: 44816 | B13: 0 | C13: 0 | D13: 0 | E13: 0 | F13: 0 | G13: 0 | H13: 0 | I13: 0 | J13: 0 | K13: 0 | L13: 0 | M13: 0 | N13: 0 | O13: 0 | P13: 0
A14: 44817 | B14: 304.47 | C14: 211.57 | D14: 22.8 | L14: 75 | M14: =C14+D14+E14+F14+G14+H14+I14+J14+L14+K14 -> 309.37 | N14: =L14-O14 -> 70.1 | O14: =M14-B14-F14 -> 4.9 | P14: 83.05
A15: 44818 | B15: 400.17 | C15: 182.15 | D15: 20.2 | L15: 200 | M15: =C15+D15+E15+F15+G15+H15+I15+J15+L15+K15 -> 402.35 | N15: =L15-O15 -> 197.82 | O15: =M15-B15-F15 -> 2.18 | P15: 83.94
A16: 44819 | B16: 886.85 | C16: 152.51 | D16: 24.5 | K16: 544 | L16: 165 | M16: =C16+D16+E16+F16+G16+H16+I16+J16+L16+K16 -> 886.01 | N16: =L16-O16 -> 165.84 | O16: =M16-B16-F16 -> -0.84 | P16: 83.26
A17: 44820 | B17: 967.99 | C17: 613.75 | D17: 40.24 | L17: 315.3 | M17: =C17+D17+E17+F17+G17+H17+I17+J17+L17+K17 -> 969.29 | N17: =L17-O17 -> 314 | O17: =M17-B17-F17 -> 1.3 | P17: 78.56
A18: 44821 | B18: 1444.28 | C18: 811.98 | D18: 88.4 | L18: 545 | M18: =C18+D18+E18+F18+G18+H18+I18+J18+L18+K18 -> 1445.38 | N18: =L18-O18 -> 543.9 | O18: =M18-B18-F18 -> 1.1 | P18: 80.96
A19: 44822 | B19: 1811.36 | C19: 1080.9 | D19: 136.66 | L19: 590 | M19: =C19+D19+E19+F19+G19+H19+I19+J19+L19+K19 -> 1807.56 | N19: =L19-O19 -> 593.8 | O19: =M19-B19-F19 -> -3.8 | P19: 73.66
A20: 44823 | B20: 0 | C20: 0 | D20: 0 | E20: 0 | L20: 0 | M20: 0 | N20: =L20-O20 -> 0 | O20: =M20-B20-F20 -> 0
A21: 44824 | B21: 663.66 | C21: 313.3 | D21: 35.4 | L21: 315 | M21: =C21+D21+E21+F21+G21+H21+I21+J21+L21+K21 -> 663.7 | N21: =L21-O21 -> 314.96 | O21: =M21-B21-F21 -> 0.04 | P21: 73.64
A22: 44825 | B22: 604.84 | C22: 359.46 | D22: 43.8 | H22: 18.9 | L22: 185 | M22: =C22+D22+E22+F22+G22+H22+I22+J22+L22+K22 -> 607.16 | N22: =L22-O22 -> 182.68 | O22: =M22-B22-F22 -> 2.32 | P22: 73.29
A23: 44826 | B23: 634.63 | C23: 337.75 | D23: 46.3 | L23: 250 | M23: =C23+D23+E23+F23+G23+H23+I23+J23+L23+K23 -> 634.05 | N23: =L23-O23 -> 250.58 | O23: =M23-B23-F23 -> -0.58 | P23: 72.04
A24: 44827 | B24: 847.18 | C24: 594.48 | D24: 59.4 | L24: 204.36 | M24: =C24+D24+E24+F24+G24+H24+I24+J24+L24+K24 -> 858.24 | N24: =L24-O24 -> 193.3 | O24: =M24-B24-F24 -> 11.06 | P24: 71.04
A25: 44828 | B25: 1289.6 | C25: 840.1 | D25: 107.1 | E25: 3.85 | L25: =329.83+15 -> 344.83 | M25: =C25+D25+E25+F25+G25+H25+I25+J25+L25+K25 -> 1295.88 | N25: =L25-O25 -> 338.55 | O25: =M25-B25-F25 -> 6.28 | P25: 80.87
A26: 44829 | B26: 1208.78 | C26: 599.66 | D26: 170.63 | H26: =29+18.9 -> 47.9 | J26: 18.9 | L26: 410.79 | M26: =C26+D26+E26+F26+G26+H26+I26+J26+L26+K26 -> 1247.88 | N26: =L26-O26 -> 371.69 | O26: =M26-B26-F26 -> 39.1 | P26: 76.66
A27: 44830 | B27: 0 | C27: 0 | D27: 0 | L27: 0 | M27: 0 | N27: =L27-O27 -> 0 | O27: =M27-B27-F27 -> 0 | P27: 0
A28: 44831 | B28: 443.48 | C28: 279.5 | D28: 64.48 | L28: 100 | M28: =C28+D28+E28+F28+G28+H28+I28+J28+L28+K28 -> 443.98 | N28: =L28-O28 -> 99.5 | O28: =M28-B28-F28 -> 0.5 | P28: 76.16
A29: 44832 | B29: 300.5 | C29: 202.4 | D29: 26 | L29: 70 | M29: =C29+D29+E29+F29+G29+H29+I29+J29+L29+K29 -> 298.4 | N29: =L29-O29 -> 72.1 | O29: =M29-B29-F29 -> -2.1 | P29: 75.36
A30: 44833 | B30: 201.06 | C30: 64.58 | D30: 40 | L30: 100 | M30: =C30+D30+E30+F30+G30+H30+I30+J30+L30+K30 -> 204.58 | N30: =L30-O30 -> 96.48 | O30: =M30-B30-F30 -> 3.52 | P30: 75.36
A31: 44834 | B31: 420 | C31: 279.5 | D31: 41.2 | H31: 18.9 | L31: 80 | M31: =C31+D31+E31+F31+G31+H31+I31+J31+L31+K31 -> 419.6 | N31: =L31-O31 -> 80.4 | O31: =M31-B31-F31 -> -0.4 | P31: 74.77
M32: =C32+D32+E32+F32+G32+H32+I32+J32+L32+K32 -> 0 | N32: =L32-O32 -> 0 | O32: =M32-B32-F32 -> 0
M33: =C33+D33+E33+F33+G33+H33+I33+J33+L33+K33 -> 0 | N33: =L33-O33 -> 0 | O33: =M33-B33-F33 -> 0
A34: TOTAL | M34: =SUM(M2:M33) -> 22317.76 | N34: =M34-O34 -> 22165.4 | O34: =SUM(O2:O33) -> 152.36

Sheet Novembro
B1: FECHO DO DIA | C1: SALT PAY | D1: SANTANDER | E1: GASTOS C/RECIBO | F1: GASTOS S/RECIBO | G1: GLOVO | H1: UBER EATS | I1: VOLUP | J1: BOLT | K1: Transf. Bancária | L1: NUMERARIO | M1: TOTAL | N1: DEPOSITO | O1: EXTRA | P1: FUNDO CAIXA | R1: Num cert
A2: 44866 | B2: 770.28 | C2: 555.58 | D2: 65.8 | L2: 150 | M2: =C2+D2+E2+F2+G2+H2+I2+J2+L2 -> 771.38 | N2: =L2-O2 -> 148.9 | O2: =M2-B2-F2 -> 1.1 | P2: 73.33
A3: 44867 | B3: 276.18 | C3: 126.46 | D3: 35.98 | L3: 115 | M3: =C3+D3+E3+F3+G3+H3+I3+J3+L3 -> 277.44 | N3: =L3-O3 -> 113.74 | O3: =M3-B3-F3 -> 1.26 | P3: 73.89
A4: 44868 | B4: 279.3 | C4: 202.3 | D4: 12.4 | H4: 20.9 | L4: 50 | M4: =C4+D4+E4+F4+G4+H4+I4+J4+L4+K4 -> 285.6 | N4: =L4-O4 -> 43.7 | O4: =M4-B4-F4 -> 6.3 | P4: 77.29
A5: 44869 | B5: 438.72 | C5: 235.12 | D5: 44.9 | H5: 93.6 | L5: 70 | M5: =C5+D5+E5+F5+G5+H5+I5+J5+L5+K5 -> 443.62 | N5: =L5-O5 -> 65.1 | O5: =M5-B5-F5 -> 4.9 | P5: 72.9
A6: 44870 | B6: 1158.47 | C6: 627.95 | D6: 183.4 | H6: 18.9 | L6: 320 | M6: =C6+D6+E6+F6+G6+H6+I6+J6+L6+K6 -> 1150.25 | N6: =L6-O6 -> 328.22 | O6: =M6-B6-F6 -> -8.22 | P6: 76
A7: 44871 | B7: 750.68 | C7: 404.98 | D7: 114.1 | H7: 83.7 | L7: 150 | M7: =C7+D7+E7+F7+G7+H7+I7+J7+L7+K7 -> 752.78 | N7: =L7-O7 -> 147.9 | O7: =M7-B7-F7 -> 2.1 | P7: 73.1
A8: 44872 | B8: 0 | C8: 0 | D8: 0 | E8: 0 | F8: 0 | G8: 0 | H8: 0 | I8: 0 | J8: 0 | K8: 0 | L8: 0 | M8: =C8+D8+E8+F8+G8+H8+I8+J8+L8+K8 -> 0 | N8: 0 | O8: 0 | P8: 0
A9: 44873 | B9: 76.7 | C9: 25.5 | D9: 3.8 | H9: 18.9 | L9: 25 | M9: =C9+D9+E9+F9+G9+H9+I9+J9+L9+K9 -> 73.2 | N9: =L9-O9 -> 28.5 | O9: =M9-B9-F9 -> -3.5
A10: 44874 | B10: 130 | C10: 54.1 | D10: 27 | L10: 40 | M10: =C10+D10+E10+F10+G10+H10+I10+J10+L10+K10 -> 121.1 | N10: =L10-O10 -> 48.9 | O10: =M10-B10-F10 -> -8.9
A11: 44875 | B11: 286.22 | C11: 146.2 | D11: 11.4 | L11: 130 | M11: =C11+D11+E11+F11+G11+H11+I11+J11+L11+K11 -> 287.6 | N11: =L11-O11 -> 128.62 | O11: =M11-B11-F11 -> 1.38 | P11: 75.86
A12: 44876 | B12: 345.57 | C12: 205.48 | D12: 50 | L12: 95 | M12: =C12+D12+E12+F12+G12+H12+I12+J12+L12+K12 -> 350.48 | N12: =L12-O12 -> 90.09 | O12: =M12-B12-F12 -> 4.91 | P12: 70.96
A13: 44877 | B13: 1435.64 | C13: 847.52 | D13: 169.5 | H13: 74.7 | L13: 365 | M13: =C13+D13+E13+F13+G13+H13+I13+J13+L13+K13 -> 1456.72 | N13: =L13-O13 -> 343.92 | O13: =M13-B13-F13 -> 21.08 | P13: 70.53
A14: 44878 | B14: 443.78 | C14: 265.28 | D14: 49 | L14: 115 | M14: =C14+D14+E14+F14+G14+H14+I14+J14+L14+K14 -> 429.28 | N14: =L14-O14 -> 129.5 | O14: =M14-B14-F14 -> -14.5 | P14: 76.74
A15: 44879 | B15: 0 | C15: 0 | D15: 0 | E15: 0 | F15: 0 | G15: 0 | H15: 0 | I15: 0 | J15: 0 | K15: 0 | L15: 0 | M15: 0 | N15: 0 | O15: 0
A16: 44880 | B16: 192.14 | C16: 172.44 | D16: 0 | L16: 20 | M16: =C16+D16+E16+F16+G16+H16+I16+J16+L16+K16 -> 192.44 | N16: =L16-O16 -> 19.7 | O16: =M16-B16-F16 -> 0.3 | P16: 76.74
A17: 44881 | B17: 59.2 | C17: 59.2 | D17: 0 | L17: 0 | M17: =C17+D17+E17+F17+G17+H17+I17+J17+L17+K17 -> 59.2 | N17: =L17-O17 -> 0 | O17: =M17-B17-F17 -> 0 | P17: 74.46
A18: 44882 | B18: 155.76 | C18: 88.76 | D18: 4.8 | L18: 65 | M18: =C18+D18+E18+F18+G18+H18+I18+J18+L18+K18 -> 158.56 | N18: =L18-O18 -> 62.2 | O18: =M18-B18-F18 -> 2.8 | P18: 70.51
A19: 44883 | B19: 176.18 | C19: 102.28 | D19: 20.5 | L19: 30 | M19: =C19+D19+E19+F19+G19+H19+I19+J19+L19+K19 -> 152.78 | N19: =L19-O19 -> 53.4 | O19: =M19-B19-F19 -> -23.4 | P19: 75.01
A20: 44884 | B20: 386.4 | C20: 253.1 | D20: 48.2 | E20: 11.7 | H20: 18.9 | L20: 55 | M20: =C20+D20+E20+F20+G20+H20+I20+J20+L20+K20 -> 386.9 | N20: =L20-O20 -> 54.5 | O20: =M20-B20-F20 -> 0.5 | P20: 74.54
A21: 44885 | B21: 340.76 | C21: 168.18 | D21: 63.54 | H21: 18.9 | L21: 90 | M21: =C21+D21+E21+F21+G21+H21+I21+J21+L21+K21 -> 340.62 | N21: =L21-O21 -> 90.14 | O21: =M21-B21-F21 -> -0.14 | P21: 73.66
A22: 44886 | B22: 0 | C22: 0 | D22: 0 | E22: 0 | F22: 0 | G22: 0 | H22: 0 | I22: 0 | J22: 0 | K22: 0 | L22: 0 | M22: 0 | N22: =L22-O22 -> 0 | O22: 0 | P22: 0
A23: 44887 | B23: 101.72 | C23: 80.52 | D23: 13.6 | L23: 10 | M23: =C23+D23+E23+F23+G23+H23+I23+J23+L23+K23 -> 104.12 | N23: =L23-O23 -> 7.6 | O23: =M23-B23-F23 -> 2.4 | P23: 71.26
A24: 44888 | B24: 200.03 | C24: 124.13 | D24: 11.4 | L24: 60 | M24: =C24+D24+E24+F24+G24+H24+I24+J24+L24+K24 -> 195.53 | N24: =L24-O24 -> 64.5 | O24: =M24-B24-F24 -> -4.5
A25: 44889 | B25: 104.7 | C25: 55.2 | D25: 0 | L25: 50 | M25: =C25+D25+E25+F25+G25+H25+I25+J25+L25+K25 -> 105.2 | N25: =L25-O25 -> 49.5 | O25: =M25-B25-F25 -> 0.5 | P25: 75.26
A26: 44890 | B26: 518.92 | C26: 121.4 | D26: 28.9 | G26: 18.9 | H26: 18.9 | K26: 254.22 | L26: 75 | M26: =C26+D26+E26+F26+G26+H26+I26+J26+L26+K26 -> 517.32 | N26: =L26-O26 -> 76.6 | O26: =M26-B26-F26 -> -1.6
A27: 44891 | B27: 777.96 | C27: 524.44 | D27: 78.32 | L27: 175 | M27: =C27+D27+E27+F27+G27+H27+I27+J27+L27+K27 -> 777.76 | N27: =L27-O27 -> 175.2 | O27: =M27-B27-F27 -> -0.2 | P27: 76.65
A28: 44892 | B28: 379.81 | C28: 192.93 | D28: 107.18 | L28: 100 | M28: =C28+D28+E28+F28+G28+H28+I28+J28+L28+K28 -> 400.11 | N28: =L28-O28 -> 79.7 | O28: =M28-B28-F28 -> 20.3 | P28: 72.76
A29: 44893 | B29: 675 | C29: 0 | D29: 0 | K29: 675 | L29: 0 | M29: =C29+D29+E29+F29+G29+H29+I29+J29+L29+K29 -> 675 | N29: =L29-O29 -> 0 | O29: =M29-B29-F29 -> 0
A30: 44894 | B30: 0 | C30: 0 | D30: 0 | L30: 0 | M30: =C30+D30+E30+F30+G30+H30+I30+J30+L30+K30 -> 0 | N30: =L30-O30 -> 0 | O30: =M30-B30-F30 -> 0
A31: 44895 | B31: 0 | C31: 0 | D31: 0 | L31: 0 | M31: =C31+D31+E31+F31+G31+H31+I31+J31+L31+K31 -> 0 | N31: =L31-O31 -> 0 | O31: =M31-B31-F31 -> 0
B32: 0 | C32: 0 | D32: 0 | L32: 0 | M32: =C32+D32+E32+F32+G32+H32+I32+J32+L32+K32 -> 0 | N32: =L32-O32 -> 0 | O32: 0
M33: =C33+D33+E33+F33+G33+H33+I33+J33+L33+K33 -> 0 | N33: =L33-O33 -> 0 | O33: =M33-B33-F33 -> 0
A34: TOTAL | M34: =SUM(M2:M33) -> 10464.99 | N34: =M34-O34 -> 10460.12 | O34: =SUM(O2:O33) -> 4.87

Sheet Maio 23
B1: FECHO DO DIA | C1: SALT PAY | D1: SANTANDER | E1: GASTOS C/RECIBO | F1: GASTOS S/RECIBO | G1: GLOVO | H1: UBER EATS | I1: VOLUP | J1: BOLT | K1: Transf. Bancária | L1: NUMERARIO | M1: TOTAL | N1: DEPOSITO | O1: EXTRA | P1: FUNDO CAIXA | R1: Num cert
A2: 45047 | B2: 0 | M2: =C2+D2+E2+F2+G2+H2+I2+J2+L2+K2 -> 0 | N2: =L2-O2 -> 0 | O2: =M2-B2-F2 -> 0
A3: 45048 | B3: 805.8 | C3: 419.7 | D3: 18.7 | H3: 37.8 | L3: 330 | M3: =C3+D3+E3+F3+G3+H3+I3+J3+L3+K3 -> 806.2 | N3: =L3-O3 -> 329.6 | O3: =M3-B3-F3 -> 0.4
A4: 45049 | B4: 291.6 | C4: 176.2 | D4: 64.8 | L4: 50 | M4: =C4+D4+E4+F4+G4+H4+I4+J4+L4+K4 -> 291 | N4: =L4-O4 -> 50.6 | O4: =M4-B4-F4 -> -0.6
A5: 45050 | B5: 477.66 | C5: 354.46 | D5: 26.2 | L5: 100 | M5: =C5+D5+E5+F5+G5+H5+I5+J5+L5+K5 -> 480.66 | N5: =L5-O5 -> 97 | O5: =M5-B5-F5 -> 3 | P5: 74.04
A6: 45051 | B6: 850.52 | C6: 507.22 | D6: 76.91 | H6: 39.9 | K6: 26.55 | L6: 200 | M6: =C6+D6+E6+F6+G6+H6+I6+J6+L6+K6 -> 850.58 | N6: =L6-O6 -> 199.94 | O6: =M6-B6-F6 -> 0.06 | P6: 73.56
A7: 45052 | B7: 1603.78 | C7: 1021.98 | D7: 134.8 | H7: 37.8 | L7: 420 | M7: =C7+D7+E7+F7+G7+H7+I7+J7+L7+K7 -> 1614.58 | N7: =L7-O7 -> 409.2 | O7: =M7-B7-F7 -> 10.8 | P7: 72.61
A8: 45053 | B8: 1891.1 | C8: 1404.9 | D8: 68.8 | H8: 42 | L8: 375 | M8: =C8+D8+E8+F8+G8+H8+I8+J8+L8+K8 -> 1890.7 | N8: =L8-O8 -> 375.4 | O8: =M8-B8-F8 -> -0.4
A9: 45054 | B9: 0 | M9: =C9+D9+E9+F9+G9+H9+I9+J9+L9+K9 -> 0 | N9: =L9-O9 -> 0 | O9: =M9-B9-F9 -> 0
A10: 45055 | B10: 360.42 | C10: 181.7 | D10: 41.02 | L10: 140 | M10: =C10+D10+E10+F10+G10+H10+I10+J10+L10+K10 -> 362.72 | N10: =L10-O10 -> 137.7 | O10: =M10-B10-F10 -> 2.3 | P10: 72.61
A11: 45056 | B11: 368.9 | C11: 221.19 | D11: 10.5 | K11: 55.62 | L11: 90 | M11: =C11+D11+E11+F11+G11+H11+I11+J11+L11+K11 -> 377.31 | N11: =L11-O11 -> 81.59 | O11: =M11-B11-F11 -> 8.41
A12: 45057 | B12: 370.38 | C12: 255.08 | D12: 17.5 | L12: 100 | M12: =C12+D12+E12+F12+G12+H12+I12+J12+L12+K12 -> 372.58 | N12: =L12-O12 -> 97.8 | O12: =M12-B12-F12 -> 2.2
A13: 45058 | B13: 827.7 | C13: 511.72 | D13: 57.6 | H13: 18.9 | K13: 95.88 | L13: 155 | M13: =C13+D13+E13+F13+G13+H13+I13+J13+L13+K13 -> 839.1 | N13: =L13-O13 -> 143.6 | O13: =M13-B13-F13 -> 11.4
A14: 45059 | B14: 1588.41 | C14: 1052 | D14: 133 | H14: 37.8 | L14: 370 | M14: =C14+D14+E14+F14+G14+H14+I14+J14+L14+K14 -> 1592.8 | N14: =L14-O14 -> 365.61 | O14: =M14-B14-F14 -> 4.39
A15: 45060 | B15: 1816.31 | C15: 1279.75 | D15: 113.46 | H15: 18.9 | L15: 410 | M15: =C15+D15+E15+F15+G15+H15+I15+J15+L15+K15 -> 1822.11 | N15: =L15-O15 -> 404.2 | O15: =M15-B15-F15 -> 5.8 | P15: 70.15
A16: 45061 | B16: 554.7 | C16: 440.3 | D16: 29.8 | L16: 90 | M16: =C16+D16+E16+F16+G16+H16+I16+J16+L16+K16 -> 560.1 | N16: =L16-O16 -> 84.6 | O16: =M16-B16-F16 -> 5.4
A17: 45062 | B17: 467.38 | C17: 233.08 | D17: 18.2 | H17: 18.9 | L17: 200 | M17: =C17+D17+E17+F17+G17+H17+I17+J17+L17+K17 -> 470.18 | N17: =L17-O17 -> 197.2 | O17: =M17-B17-F17 -> 2.8
A18: 45063 | B18: 589.8 | C18: 310.7 | D18: 34.6 | H18: 34.1 | L18: 210 | M18: =C18+D18+E18+F18+G18+H18+I18+J18+L18+K18 -> 589.4 | N18: =L18-O18 -> 210.4 | O18: =M18-B18-F18 -> -0.4
A19: 45064 | B19: 544.73 | C19: 396.53 | D19: 38.3 | L19: 110 | M19: =C19+D19+E19+F19+G19+H19+I19+J19+L19+K19 -> 544.83 | N19: =L19-O19 -> 109.9 | O19: =M19-B19-F19 -> 0.1 | P19: 63.78
A20: 45065 | B20: 1296.86 | C20: 565.32 | D20: 127.5 | H20: 94.6 | K20: =236+142.94 -> 378.94 | L20: 135 | M20: =C20+D20+E20+F20+G20+H20+I20+J20+L20+K20 -> 1301.36 | N20: =L20-O20 -> 130.5 | O20: =M20-B20-F20 -> 4.5
A21: 45066 | B21: 1400.19 | C21: 987.99 | D21: 117.9 | H21: 41 | L21: 250 | M21: =C21+D21+E21+F21+G21+H21+I21+J21+L21+K21 -> 1396.89 | N21: =L21-O21 -> 253.3 | O21: =M21-B21-F21 -> -3.3 | P21: 66.58
A22: 45067 | B22: 1700.19 | C22: 1167.55 | D22: 126.06 | L22: 410 | M22: =C22+D22+E22+F22+G22+H22+I22+J22+L22+K22 -> 1703.61 | N22: =L22-O22 -> 406.58 | O22: =M22-B22-F22 -> 3.42
A23: 45068 | B23: 250.1 | C23: 125.3 | D23: 26.6 | L23: 100 | M23: =C23+D23+E23+F23+G23+H23+I23+J23+L23+K23 -> 251.9 | N23: =L23-O23 -> 98.2 | O23: =M23-B23-F23 -> 1.8
A24: 45069 | B24: 567.76 | C24: 315.4 | D24: 46.8 | L24: 210 | M24: =C24+D24+E24+F24+G24+H24+I24+J24+L24+K24 -> 572.2 | N24: =L24-O24 -> 205.56 | O24: =M24-B24-F24 -> 4.44 | P24: 74
A25: 45070 | B25: 451.4 | C25: 296.8 | D25: 2.9 | L25: 160 | M25: =C25+D25+E25+F25+G25+H25+I25+J25+L25+K25 -> 459.7 | N25: =L25-O25 -> 151.7 | O25: =M25-B25-F25 -> 8.3 | P25: 64.31
A26: 45071 | B26: 607.4 | C26: 437.9 | D26: 20.1 | H26: 37.8 | L26: 110 | M26: =C26+D26+E26+F26+G26+H26+I26+J26+L26+K26 -> 605.8 | N26: =L26-O26 -> 111.6 | O26: =M26-B26-F26 -> -1.6
A27: 45072 | B27: =554.7+136.1 -> 690.8 | C27: 417.85 | D27: 21.2 | L27: =130+120 -> 250 | M27: =C27+D27+E27+F27+G27+H27+I27+J27+L27+K27 -> 689.05 | N27: =L27-O27 -> 251.75 | O27: =M27-B27-F27 -> -1.75
A28: 45073 | B28: =1198.38+118.7 -> 1317.08 | C28: 972.88 | D28: 42.7 | H28: 55.8 | L28: =170+75 -> 245 | M28: =C28+D28+E28+F28+G28+H28+I28+J28+L28+K28 -> 1316.38 | N28: =L28-O28 -> 245.7 | O28: =M28-B28-F28 -> -0.7
A29: 45074 | B29: 1096.08 | C29: 577.68 | D29: 72.1 | H29: 65.8 | K29: 260 | L29: 135 | M29: =C29+D29+E29+F29+G29+H29+I29+J29+L29+K29 -> 1110.58 | N29: =L29-O29 -> 120.5 | O29: =M29-B29-F29 -> 14.5
A30: 45075 | B30: 391.86 | C30: 97.12 | D30: 14.4 | K30: 189.66 | L30: 90 | M30: =C30+D30+E30+F30+G30+H30+I30+J30+L30+K30 -> 391.18 | N30: =L30-O30 -> 90.68 | O30: =M30-B30-F30 -> -0.68
A31: 45076 | B31: 536.4 | C31: 251.7 | D31: 57.9 | L31: 225 | M31: =C31+D31+E31+F31+G31+H31+I31+J31+L31+K31 -> 534.6 | N31: =L31-O31 -> 226.8 | O31: =M31-B31-F31 -> -1.8 | P31: 64.36
A32: 45077 | B32: 573.64 | C32: 257.86 | D32: =11.4+16 -> 27.4 | H32: 18.9 | K32: 113.28 | L32: 155 | M32: =C32+D32+E32+F32+G32+H32+I32+J32+L32+K32 -> 572.44 | N32: =L32-O32 -> 156.2 | O32: =M32-B32-F32 -> -1.2
M33: =C33+D33+E33+F33+G33+H33+I33+J33+L33+K33 -> 0 | N33: =L33-O33 -> 0 | O33: =M33-B33-F33 -> 0
A34: TOTAL | M34: =SUM(M2:M33) -> 24370.54 | N34: =M34-O34 -> 24288.95 | O34: =SUM(O2:O33) -> 81.59

Sheet Jun 23 
B1: FECHO DO DIA | C1: SALT PAY | D1: SANTANDER | E1: GASTOS C/RECIBO | F1: GASTOS S/RECIBO | G1: GLOVO | H1: UBER EATS | I1: VOLUP | J1: BOLT | K1: Transf. Bancária | L1: NUMERARIO | M1: TOTAL | N1: DEPOSITO | O1: EXTRA | P1: FUNDO CAIXA | R1: Num cert
A2: 45078 | B2: 709.14 | C2: 408.86 | D2: 62.74 | H2: 91.7 | L2: 160 | M2: =C2+D2+E2+F2+G2+H2+I2+J2+L2+K2 -> 723.3 | N2: =L2-O2 -> 145.84 | O2: =M2-B2-F2 -> 14.16
A3: 45079 | B3: 791.12 | C3: 464.84 | D3: 53.28 | L3: 270 | M3: =C3+D3+E3+F3+G3+H3+I3+J3+L3+K3 -> 788.12 | N3: =L3-O3 -> 273 | O3: =M3-B3-F3 -> -3
A4: 45080 | B4: 1383.24 | C4: 981.14 | D4: 81.5 | L4: 350 | M4: =C4+D4+E4+F4+G4+H4+I4+J4+L4+K4 -> 1412.64 | N4: =L4-O4 -> 320.6 | O4: =M4-B4-F4 -> 29.4
A5: 45081 | B5: 1037.42 | C5: 630.1 | D5: 47.5 | L5: 360 | M5: =C5+D5+E5+F5+G5+H5+I5+J5+L5+K5 -> 1037.6 | N5: =L5-O5 -> 359.82 | O5: =M5-B5-F5 -> 0.18
A6: 45082 | B6: 485.85 | C6: 324.55 | D6: 29.7 | L6: 135 | M6: =C6+D6+E6+F6+G6+H6+I6+J6+L6+K6 -> 489.25 | N6: =L6-O6 -> 131.6 | O6: =M6-B6-F6 -> 3.4
A7: 45083 | B7: 567.26 | C7: 291.6 | D7: 90.1 | H7: 32.9 | K7: 16.96 | L7: 135 | M7: =C7+D7+E7+F7+G7+H7+I7+J7+L7+K7 -> 566.56 | N7: =L7-O7 -> 135.7 | O7: =M7-B7-F7 -> -0.7
A8: 45084 | B8: 888.04 | C8: 193.8 | D8: 44 | K8: =503.59 + 57.85 -> 561.44 | L8: 90 | M8: =C8+D8+E8+F8+G8+H8+I8+J8+L8+K8 -> 889.24 | N8: =L8-O8 -> 88.8 | O8: =M8-B8-F8 -> 1.2
A9: 45085 | B9: 655 | C9: 282.5 | D9: 42.94 | H9: 34 | K9: 176.16 | L9: 120 | M9: =C9+D9+E9+F9+G9+H9+I9+J9+L9+K9 -> 655.6 | N9: =L9-O9 -> 119.4 | O9: =M9-B9-F9 -> 0.6
A10: 45086 | B10: 1176.62 | C10: 428 | D10: 31.5 | K10: 443.22 | L10: 290 | M10: =C10+D10+E10+F10+G10+H10+I10+J10+L10+K10 -> 1192.72 | N10: =L10-O10 -> 273.9 | O10: =M10-B10-F10 -> 16.1
A11: 45087 | B11: 1572.48 | C11: 1057.89 | D11: 114.3 | H11: 18.9 | K11: 60.19 | L11: 330 | M11: =C11+D11+E11+F11+G11+H11+I11+J11+L11+K11 -> 1581.28 | N11: =L11-O11 -> 321.2 | O11: =M11-B11-F11 -> 8.8
A12: 45088 | B12: 1374.1 | C12: 915.9 | D12: 119.4 | H12: 18.9 | L12: 320 | M12: =C12+D12+E12+F12+G12+H12+I12+J12+L12+K12 -> 1374.2 | N12: =L12-O12 -> 319.9 | O12: =M12-B12-F12 -> 0.1
A13: 45089 | B13: 640.96 | C13: 439.02 | D13: 40.24 | H13: 52.8 | L13: 110 | M13: =C13+D13+E13+F13+G13+H13+I13+J13+L13+K13 -> 642.06 | N13: =L13-O13 -> 108.9 | O13: =M13-B13-F13 -> 1.1
A14: 45090 | B14: 537.84 | C14: 329.74 | D14: 24.2 | H14: 18.9 | L14: 165 | M14: =C14+D14+E14+F14+G14+H14+I14+J14+L14+K14 -> 537.84 | N14: =L14-O14 -> 165 | O14: =M14-B14-F14 -> -1.1368684e-13 | P14: 76.81
A15: 45091 | B15: 543.35 | C15: 356.15 | D15: 22 | H15: 19.8 | L15: 145 | M15: =C15+D15+E15+F15+G15+H15+I15+J15+L15+K15 -> 542.95 | N15: =L15-O15 -> 145.4 | O15: =M15-B15-F15 -> -0.4
A16: 45092 | B16: 810.28 | C16: 442.4 | D16: 103.88 | H16: 33.1 | L16: 235 | M16: =C16+D16+E16+F16+G16+H16+I16+J16+L16+K16 -> 814.38 | N16: =L16-O16 -> 230.9 | O16: =M16-B16-F16 -> 4.1
A17: 45093 | B17: 1097.53 | C17: 585.82 | D17: 82.4 | H17: 60.8 | K17: 87.91 | L17: 280 | M17: =C17+D17+E17+F17+G17+H17+I17+J17+L17+K17 -> 1096.93 | N17: =L17-O17 -> 280.6 | O17: =M17-B17-F17 -> -0.6 | P17: 76.83
A18: 45094 | B18: 1773.93 | C18: 1220.82 | D18: 128.91 | H18: 73.7 | L18: 350 | M18: =C18+D18+E18+F18+G18+H18+I18+J18+L18+K18 -> 1773.43 | N18: =L18-O18 -> 350.5 | O18: =M18-B18-F18 -> -0.5
A19: 45095 | B19: 1406.86 | C19: 863.16 | D19: 111.1 | H19: 51.9 | L19: 395 | M19: =C19+D19+E19+F19+G19+H19+I19+J19+L19+K19 -> 1421.16 | N19: =L19-O19 -> 380.7 | O19: =M19-B19-F19 -> 14.3
A20: 45096 | B20: 498.32 | C20: 301.54 | D20: 20 | K20: 25.08 | L20: 150 | M20: =C20+D20+E20+F20+G20+H20+I20+J20+L20+K20 -> 496.62 | N20: =L20-O20 -> 151.7 | O20: =M20-B20-F20 -> -1.7
A21: 45097 | B21: 560.44 | C21: 354.82 | D21: 22.2 | H21: 32.9 | L21: 170 | M21: =C21+D21+E21+F21+G21+H21+I21+J21+L21+K21 -> 579.92 | N21: =L21-O21 -> 150.52 | O21: =M21-B21-F21 -> 19.48
